Workbook

Sheet PANDUAN
A1: RUMUSAN URUSETIA KEHAKIMAN | CDKK @FESMA 2026 | PANDUAN
A2: Baca panduan ini sekali sebelum guna. Sel KUNING = isi/pilih. Sel BIRU = formula, jangan taip.
B5: TUJUAN
B6: A | C6: Fungsi fail | D6: Mengumpul markah tiga hakim dan skor 25 juri awam daripada borang Google Sheet alternatif, mengira purata, sisihan, kedudukan dan pecah seri secara automatik, dan menyokong pengesahan dua Urusetia Kehakiman (GP 15.6).
B7: B | C7: Siapa boleh buka | D7: Hanya Urusetia Kehakiman dan Ketua Hakim. Jangan kongsi kepada hakim atau juri lain.
B8: C | C8: Hubungan dengan Portal | D8: Fail ini tidak bersambung dengan Apps Script dan tidak menggantikan Konsol Kehakiman melainkan Portal tidak boleh digunakan.
B10: ALIRAN KERJA
B11: 1 | C11: Markah hakim | D11: Bila borang hakim berstatus SEDIA DISERAH, buka tab SALIN borang itu, salin A5:M18 dan tampal NILAI SAHAJA ke sel A6 pada tab HAKIM_H1, H2 atau H3. Jika hakim mengisi kertas, taip ke borang hakim dahulu atau terus ke tab HAKIM.
B12: 2 | C12: Skor juri awam | D12: Bila borang juri SEDIA DISERAH, salin G9:G22 (lajur JUMLAH) dan tampal NILAI SAHAJA ke lajur juri berkenaan dalam tab JURI (Juri 01 hingga 25), bermula baris 6. Sel kosong = juri tidak mengundi pasukan itu.
B13: 3 | C13: Tarik diri atau BATAL | D13: Tukar lajur Status pada tab KEPUTUSAN. Pasukan BATAL mendapat markah akhir 0 dan tidak disusun. Tarik diri dikecualikan.
B14: 4 | C14: Semak | D14: Buka tab SEMAKAN: semua lajur Semakan tab HAKIM mesti LENGKAP bagi pasukan aktif dan kiraan semula mesti SAMA.
B15: 5 | C15: Pengesahan | D15: Dua Urusetia mengesahkan di bahagian Pengesahan tab KEPUTUSAN. Status bertukar MUKTAMAD hanya bila semua syarat dipenuhi.
B16: 6 | C16: Lihat keputusan | D16: Tab DASHBOARD memaparkan kad ringkasan, kedudukan panel hakim, anugerah juri awam dan carta, dikemas kini automatik.
B18: PERATURAN PENGIRAAN
B19: 1 | C19: Jumlah seorang hakim | D19: Sembilan komponen ditolak penalti hakim itu (aset 0 hingga 3, budi bicara 0 hingga 2), tidak kurang daripada 0.
B20: 2 | C20: Markah akhir | D20: Purata jumlah KETIGA-TIGA hakim, dibundarkan kepada 2 perpuluhan (sama seperti Portal). Purata hanya dikira bila ketiga-tiga hakim lengkap.
B21: 3 | C21: Sisihan | D21: (jumlah tertinggi tolak terendah) / purata x 100. Lebih 20% dibenderakan untuk semakan, bukan untuk pembetulan automatik.
B22: 4 | C22: Pecah seri | D22: Markah akhir sama dileraikan ikut jumlah komponen tiga hakim: Kreativiti, Kandungan, Canva, AI, CapCut, Audio, Persembahan, Etika, AURORA. Jika masih sama, panel berbincang dan merekod keputusan.
B23: 5 | C23: Juri awam | D23: Sumbangan seorang juri = jumlah tiga aspek / 30 x 4. Skor pasukan = hasil tambah sumbangan semua juri, maksimum 100. Minimum 5 undi untuk layak, lebih 25 undi tidak layak.
B24: 6 | C24: Anugerah juri | D24: Anugerah Pilihan Juri Awam berasingan daripada markah hakim dan tidak ditambah kepada markah hakim.
B26: PERINGATAN
B27: 1 | C27: Semak baris Maksimum | D27: Sebelum menampal, pastikan baris Maksimum tab HAKIM menunjukkan 20, 15, 15, 10, 10, 10, 5, 10, 5 (Kandungan 15 markah).
B28: 2 | C28: Status fail | D28: Rumusan ini sandaran. Jika Portal CDKK digunakan sebagai sistem utama, keputusan rasmi ialah daripada Konsol Kehakiman.
B29: 3 | C29: Perlindungan sel | D29: Tidak dihidupkan. Untuk melindungi sel formula: Data > Lindungi helaian dan julat > Papar amaran apabila mengedit julat ini.

Sheet DASHBOARD
A1: DASHBOARD KEPUTUSAN | CDKK @FESMA 2026
A2: Dikemas kini automatik daripada tab KEPUTUSAN, JURI dan SEMAKAN. Jangan taip di tab ini.
A5: PASUKAN AKTIF | E5: LENGKAP 3 HAKIM | I5: JURI AWAM MENGUNDI | M5: STATUS KEPUTUSAN
A6: =COUNTIF(KEPUTUSAN!D6:D19,"Aktif") | E6: =COUNTIFS(KEPUTUSAN!D6:D19,"Aktif",KEPUTUSAN!H6:H19,3)&" / "&COUNTIF(KEPUTUSAN!D6:D19,"Aktif") | I6: =COUNTIF(JURI!D20:AB20,">0")&" / 25" | M6: =IF(LEFT(KEPUTUSAN!D25,8)="MUKTAMAD","MUKTAMAD","BELUM MUKTAMAD")
A9: KEDUDUKAN PANEL HAKIM | J9: ANUGERAH PILIHAN JURI AWAM (berasingan)
A10: Ked. | B10: Pasukan | E10: Negeri | G10: Markah akhir | J10: Ked. | K10: Pasukan | N10: Skor juri | P10: Undi
A11: 1 | B11: =IFERROR(INDEX(KEPUTUSAN!$C$6:$C$19,MATCH($A11,KEPUTUSAN!$M$6:$M$19,0)),"") | E11: =IFERROR(INDEX(KEPUTUSAN!$B$6:$B$19,MATCH($A11,KEPUTUSAN!$M$6:$M$19,0)),"") | G11: =IFERROR(INDEX(KEPUTUSAN!$J$6:$J$19,MATCH($A11,KEPUTUSAN!$M$6:$M$19,0)),"") | J11: 1 | K11: =IFERROR(INDEX(KEPUTUSAN!$C$6:$C$19,MATCH($J11,KEPUTUSAN!$S$6:$S$19,0)),"") | N11: =IFERROR(INDEX(KEPUTUSAN!$Q$6:$Q$19,MATCH($J11,KEPUTUSAN!$S$6:$S$19,0)),"") | P11: =IFERROR(INDEX(KEPUTUSAN!$P$6:$P$19,MATCH($J11,KEPUTUSAN!$S$6:$S$19,0)),"")
A12: 2 | B12: =IFERROR(INDEX(KEPUTUSAN!$C$6:$C$19,MATCH($A12,KEPUTUSAN!$M$6:$M$19,0)),"") | E12: =IFERROR(INDEX(KEPUTUSAN!$B$6:$B$19,MATCH($A12,KEPUTUSAN!$M$6:$M$19,0)),"") | G12: =IFERROR(INDEX(KEPUTUSAN!$J$6:$J$19,MATCH($A12,KEPUTUSAN!$M$6:$M$19,0)),"") | J12: 2 | K12: =IFERROR(INDEX(KEPUTUSAN!$C$6:$C$19,MATCH($J12,KEPUTUSAN!$S$6:$S$19,0)),"") | N12: =IFERROR(INDEX(KEPUTUSAN!$Q$6:$Q$19,MATCH($J12,KEPUTUSAN!$S$6:$S$19,0)),"") | P12: =IFERROR(INDEX(KEPUTUSAN!$P$6:$P$19,MATCH($J12,KEPUTUSAN!$S$6:$S$19,0)),"")
A13: 3 | B13: =IFERROR(INDEX(KEPUTUSAN!$C$6:$C$19,MATCH($A13,KEPUTUSAN!$M$6:$M$19,0)),"") | E13: =IFERROR(INDEX(KEPUTUSAN!$B$6:$B$19,MATCH($A13,KEPUTUSAN!$M$6:$M$19,0)),"") | G13: =IFERROR(INDEX(KEPUTUSAN!$J$6:$J$19,MATCH($A13,KEPUTUSAN!$M$6:$M$19,0)),"") | J13: 3 | K13: =IFERROR(INDEX(KEPUTUSAN!$C$6:$C$19,MATCH($J13,KEPUTUSAN!$S$6:$S$19,0)),"") | N13: =IFERROR(INDEX(KEPUTUSAN!$Q$6:$Q$19,MATCH($J13,KEPUTUSAN!$S$6:$S$19,0)),"") | P13: =IFERROR(INDEX(KEPUTUSAN!$P$6:$P$19,MATCH($J13,KEPUTUSAN!$S$6:$S$19,0)),"")
A14: 4 | B14: =IFERROR(INDEX(KEPUTUSAN!$C$6:$C$19,MATCH($A14,KEPUTUSAN!$M$6:$M$19,0)),"") | E14: =IFERROR(INDEX(KEPUTUSAN!$B$6:$B$19,MATCH($A14,KEPUTUSAN!$M$6:$M$19,0)),"") | G14: =IFERROR(INDEX(KEPUTUSAN!$J$6:$J$19,MATCH($A14,KEPUTUSAN!$M$6:$M$19,0)),"") | J14: 4 | K14: =IFERROR(INDEX(KEPUTUSAN!$C$6:$C$19,MATCH($J14,KEPUTUSAN!$S$6:$S$19,0)),"") | N14: =IFERROR(INDEX(KEPUTUSAN!$Q$6:$Q$19,MATCH($J14,KEPUTUSAN!$S$6:$S$19,0)),"") | P14: =IFERROR(INDEX(KEPUTUSAN!$P$6:$P$19,MATCH($J14,KEPUTUSAN!$S$6:$S$19,0)),"")
A15: 5 | B15: =IFERROR(INDEX(KEPUTUSAN!$C$6:$C$19,MATCH($A15,KEPUTUSAN!$M$6:$M$19,0)),"") | E15: =IFERROR(INDEX(KEPUTUSAN!$B$6:$B$19,MATCH($A15,KEPUTUSAN!$M$6:$M$19,0)),"") | G15: =IFERROR(INDEX(KEPUTUSAN!$J$6:$J$19,MATCH($A15,KEPUTUSAN!$M$6:$M$19,0)),"") | J15: 5 | K15: =IFERROR(INDEX(KEPUTUSAN!$C$6:$C$19,MATCH($J15,KEPUTUSAN!$S$6:$S$19,0)),"") | N15: =IFERROR(INDEX(KEPUTUSAN!$Q$6:$Q$19,MATCH($J15,KEPUTUSAN!$S$6:$S$19,0)),"") | P15: =IFERROR(INDEX(KEPUTUSAN!$P$6:$P$19,MATCH($J15,KEPUTUSAN!$S$6:$S$19,0)),"")
A16: 6 | B16: =IFERROR(INDEX(KEPUTUSAN!$C$6:$C$19,MATCH($A16,KEPUTUSAN!$M$6:$M$19,0)),"") | E16: =IFERROR(INDEX(KEPUTUSAN!$B$6:$B$19,MATCH($A16,KEPUTUSAN!$M$6:$M$19,0)),"") | G16: =IFERROR(INDEX(KEPUTUSAN!$J$6:$J$19,MATCH($A16,KEPUTUSAN!$M$6:$M$19,0)),"") | J16: 6 | K16: =IFERROR(INDEX(KEPUTUSAN!$C$6:$C$19,MATCH($J16,KEPUTUSAN!$S$6:$S$19,0)),"") | N16: =IFERROR(INDEX(KEPUTUSAN!$Q$6:$Q$19,MATCH($J16,KEPUTUSAN!$S$6:$S$19,0)),"") | P16: =IFERROR(INDEX(KEPUTUSAN!$P$6:$P$19,MATCH($J16,KEPUTUSAN!$S$6:$S$19,0)),"")
A17: 7 | B17: =IFERROR(INDEX(KEPUTUSAN!$C$6:$C$19,MATCH($A17,KEPUTUSAN!$M$6:$M$19,0)),"") | E17: =IFERROR(INDEX(KEPUTUSAN!$B$6:$B$19,MATCH($A17,KEPUTUSAN!$M$6:$M$19,0)),"") | G17: =IFERROR(INDEX(KEPUTUSAN!$J$6:$J$19,MATCH($A17,KEPUTUSAN!$M$6:$M$19,0)),"") | J17: 7 | K17: =IFERROR(INDEX(KEPUTUSAN!$C$6:$C$19,MATCH($J17,KEPUTUSAN!$S$6:$S$19,0)),"") | N17: =IFERROR(INDEX(KEPUTUSAN!$Q$6:$Q$19,MATCH($J17,KEPUTUSAN!$S$6:$S$19,0)),"") | P17: =IFERROR(INDEX(KEPUTUSAN!$P$6:$P$19,MATCH($J17,KEPUTUSAN!$S$6:$S$19,0)),"")
A18: 8 | B18: =IFERROR(INDEX(KEPUTUSAN!$C$6:$C$19,MATCH($A18,KEPUTUSAN!$M$6:$M$19,0)),"") | E18: =IFERROR(INDEX(KEPUTUSAN!$B$6:$B$19,MATCH($A18,KEPUTUSAN!$M$6:$M$19,0)),"") | G18: =IFERROR(INDEX(KEPUTUSAN!$J$6:$J$19,MATCH($A18,KEPUTUSAN!$M$6:$M$19,0)),"") | J18: 8 | K18: =IFERROR(INDEX(KEPUTUSAN!$C$6:$C$19,MATCH($J18,KEPUTUSAN!$S$6:$S$19,0)),"") | N18: =IFERROR(INDEX(KEPUTUSAN!$Q$6:$Q$19,MATCH($J18,KEPUTUSAN!$S$6:$S$19,0)),"") | P18: =IFERROR(INDEX(KEPUTUSAN!$P$6:$P$19,MATCH($J18,KEPUTUSAN!$S$6:$S$19,0)),"")
A19: 9 | B19: =IFERROR(INDEX(KEPUTUSAN!$C$6:$C$19,MATCH($A19,KEPUTUSAN!$M$6:$M$19,0)),"") | E19: =IFERROR(INDEX(KEPUTUSAN!$B$6:$B$19,MATCH($A19,KEPUTUSAN!$M$6:$M$19,0)),"") | G19: =IFERROR(INDEX(KEPUTUSAN!$J$6:$J$19,MATCH($A19,KEPUTUSAN!$M$6:$M$19,0)),"") | J19: 9 | K19: =IFERROR(INDEX(KEPUTUSAN!$C$6:$C$19,MATCH($J19,KEPUTUSAN!$S$6:$S$19,0)),"") | N19: =IFERROR(INDEX(KEPUTUSAN!$Q$6:$Q$19,MATCH($J19,KEPUTUSAN!$S$6:$S$19,0)),"") | P19: =IFERROR(INDEX(KEPUTUSAN!$P$6:$P$19,MATCH($J19,KEPUTUSAN!$S$6:$S$19,0)),"")
A20: 10 | B20: =IFERROR(INDEX(KEPUTUSAN!$C$6:$C$19,MATCH($A20,KEPUTUSAN!$M$6:$M$19,0)),"") | E20: =IFERROR(INDEX(KEPUTUSAN!$B$6:$B$19,MATCH($A20,KEPUTUSAN!$M$6:$M$19,0)),"") | G20: =IFERROR(INDEX(KEPUTUSAN!$J$6:$J$19,MATCH($A20,KEPUTUSAN!$M$6:$M$19,0)),"") | J20: 10 | K20: =IFERROR(INDEX(KEPUTUSAN!$C$6:$C$19,MATCH($J20,KEPUTUSAN!$S$6:$S$19,0)),"") | N20: =IFERROR(INDEX(KEPUTUSAN!$Q$6:$Q$19,MATCH($J20,KEPUTUSAN!$S$6:$S$19,0)),"") | P20: =IFERROR(INDEX(KEPUTUSAN!$P$6:$P$19,MATCH($J20,KEPUTUSAN!$S$6:$S$19,0)),"")
A21: 11 | B21: =IFERROR(INDEX(KEPUTUSAN!$C$6:$C$19,MATCH($A21,KEPUTUSAN!$M$6:$M$19,0)),"") | E21: =IFERROR(INDEX(KEPUTUSAN!$B$6:$B$19,MATCH($A21,KEPUTUSAN!$M$6:$M$19,0)),"") | G21: =IFERROR(INDEX(KEPUTUSAN!$J$6:$J$19,MATCH($A21,KEPUTUSAN!$M$6:$M$19,0)),"") | J21: 11 | K21: =IFERROR(INDEX(KEPUTUSAN!$C$6:$C$19,MATCH($J21,KEPUTUSAN!$S$6:$S$19,0)),"") | N21: =IFERROR(INDEX(KEPUTUSAN!$Q$6:$Q$19,MATCH($J21,KEPUTUSAN!$S$6:$S$19,0)),"") | P21: =IFERROR(INDEX(KEPUTUSAN!$P$6:$P$19,MATCH($J21,KEPUTUSAN!$S$6:$S$19,0)),"")
A22: 12 | B22: =IFERROR(INDEX(KEPUTUSAN!$C$6:$C$19,MATCH($A22,KEPUTUSAN!$M$6:$M$19,0)),"") | E22: =IFERROR(INDEX(KEPUTUSAN!$B$6:$B$19,MATCH($A22,KEPUTUSAN!$M$6:$M$19,0)),"") | G22: =IFERROR(INDEX(KEPUTUSAN!$J$6:$J$19,MATCH($A22,KEPUTUSAN!$M$6:$M$19,0)),"") | J22: 12 | K22: =IFERROR(INDEX(KEPUTUSAN!$C$6:$C$19,MATCH($J22,KEPUTUSAN!$S$6:$S$19,0)),"") | N22: =IFERROR(INDEX(KEPUTUSAN!$Q$6:$Q$19,MATCH($J22,KEPUTUSAN!$S$6:$S$19,0)),"") | P22: =IFERROR(INDEX(KEPUTUSAN!$P$6:$P$19,MATCH($J22,KEPUTUSAN!$S$6:$S$19,0)),"")
... A24: 14 | B24: =IFERROR(INDEX(KEPUTUSAN!$C$6:$C$19,MATCH($A24,KEPUTUSAN!$M$6:$M$19,0)),"") | E24: =IFERROR(INDEX(KEPUTUSAN!$B$6:$B$19,MATCH($A24,KEPUTUSAN!$M$6:$M$19,0)),"") | G24: =IFERROR(INDEX(KEPUTUSAN!$J$6:$J$19,MATCH($A24,KEPUTUSAN!$M$6:$M$19,0)),"") | J24: 14 | K24: =IFERROR(INDEX(KEPUTUSAN!$C$6:$C$19,MATCH($J24,KEPUTUSAN!$S$6:$S$19,0)),"") | N24: =IFERROR(INDEX(KEPUTUSAN!$Q$6:$Q$19,MATCH($J24,KEPUTUSAN!$S$6:$S$19,0)),"") | P24: =IFERROR(INDEX(KEPUTUSAN!$P$6:$P$19,MATCH($J24,KEPUTUSAN!$S$6:$S$19,0)),"")
A26: CARTA

Sheet KEPUTUSAN
A1: KEPUTUSAN KEHAKIMAN | CDKK @FESMA 2026
A2: Markah hakim (kiri) dan skor juri awam (kanan, berasingan, tidak ditambah kepada markah hakim). Sel KUNING = Status pasukan sahaja. Selebihnya formula.
A3: STATUS PENGIRAAN | E3: =IF(COUNTIF(D6:D19,"Aktif")=COUNTIFS(D6:D19,"Aktif",H6:H19,3),"SEMUA HAKIM LENGKAP: kedudukan lengkap","SEMENTARA: "&COUNTIFS(D6:D19,"Aktif",H6:H19,3)&" daripada "&COUNTIF(D6:D19,"Aktif")&" pasukan aktif lengkap tiga hakim")
A4: MARKAH PANEL HAKIM | P4: JURI AWAM (anugerah berasingan)
A5: Bil | B5: Negeri | C5: Pasukan | D5: Status | E5: Hakim H1 | F5: Hakim H2 | G5: Hakim H3 | H5: Bil hakim lengkap | I5: Purata tiga hakim | J5: MARKAH AKHIR | K5: Sisihan % | L5: Bendera sisihan | M5: KEDUDUKAN | N5: Catatan | P5: Bil undi | Q5: Skor juri (maks 100) | R5: Kelayakan anugerah | S5: Kedudukan juri | T5: Catatan juri
A6: 1 | B6: PERLIS | C6: NOVA | D6: Aktif | E6: =IF(HAKIM_H1!$Q6="LENGKAP",HAKIM_H1!$P6,"") | F6: =IF(HAKIM_H2!$Q6="LENGKAP",HAKIM_H2!$P6,"") | G6: =IF(HAKIM_H3!$Q6="LENGKAP",HAKIM_H3!$P6,"") | H6: =COUNT(E6:G6) | I6: =IF(H6=3,ROUND(AVERAGE(E6:G6),2),"") | J6: =IF(D6="BATAL",0,IF(D6="Aktif",I6,"")) | K6: =IF(H6=3,IF(AVERAGE(E6:G6)>0,ROUND((MAX(E6:G6)-MIN(E6:G6))/AVERAGE(E6:G6)*100,0),0),"") | L6: =IF(K6="","",IF(K6>20,"SEMAK: sisihan "&K6&"%","")) | M6: =IF(D6="Tarik diri","TARIK DIRI",IF(D6="BATAL","BATAL",IF(PECAH_SERI!M6="","",PECAH_SERI!M6))) | N6: =IF(PECAH_SERI!N6<>"",PECAH_SERI!N6,IF(AND(D6="Aktif",H6<3),"Menunggu "&(3-H6)&" hakim","")) | P6: =JURI!AC6 | Q6: =JURI!AD6 | R6: =JURI!AE6 | S6: =JURI!AF6 | T6: =JURI!AG6
A7: 2 | B7: KEDAH | C7: KDH BUDDY | D7: Aktif | E7: =IF(HAKIM_H1!$Q7="LENGKAP",HAKIM_H1!$P7,"") | F7: =IF(HAKIM_H2!$Q7="LENGKAP",HAKIM_H2!$P7,"") | G7: =IF(HAKIM_H3!$Q7="LENGKAP",HAKIM_H3!$P7,"") | H7: =COUNT(E7:G7) | I7: =IF(H7=3,ROUND(AVERAGE(E7:G7),2),"") | J7: =IF(D7="BATAL",0,IF(D7="Aktif",I7,"")) | K7: =IF(H7=3,IF(AVERAGE(E7:G7)>0,ROUND((MAX(E7:G7)-MIN(E7:G7))/AVERAGE(E7:G7)*100,0),0),"") | L7: =IF(K7="","",IF(K7>20,"SEMAK: sisihan "&K7&"%","")) | M7: =IF(D7="Tarik diri","TARIK DIRI",IF(D7="BATAL","BATAL",IF(PECAH_SERI!M7="","",PECAH_SERI!M7))) | N7: =IF(PECAH_SERI!N7<>"",PECAH_SERI!N7,IF(AND(D7="Aktif",H7<3),"Menunggu "&(3-H7)&" hakim","")) | P7: =JURI!AC7 | Q7: =JURI!AD7 | R7: =JURI!AE7 | S7: =JURI!AF7 | T7: =JURI!AG7
A8: 3 | B8: PULAU PINANG | C8: RAFIQ RANGERS | D8: Aktif | E8: =IF(HAKIM_H1!$Q8="LENGKAP",HAKIM_H1!$P8,"") | F8: =IF(HAKIM_H2!$Q8="LENGKAP",HAKIM_H2!$P8,"") | G8: =IF(HAKIM_H3!$Q8="LENGKAP",HAKIM_H3!$P8,"") | H8: =COUNT(E8:G8) | I8: =IF(H8=3,ROUND(AVERAGE(E8:G8),2),"") | J8: =IF(D8="BATAL",0,IF(D8="Aktif",I8,"")) | K8: =IF(H8=3,IF(AVERAGE(E8:G8)>0,ROUND((MAX(E8:G8)-MIN(E8:G8))/AVERAGE(E8:G8)*100,0),0),"") | L8: =IF(K8="","",IF(K8>20,"SEMAK: sisihan "&K8&"%","")) | M8: =IF(D8="Tarik diri","TARIK DIRI",IF(D8="BATAL","BATAL",IF(PECAH_SERI!M8="","",PECAH_SERI!M8))) | N8: =IF(PECAH_SERI!N8<>"",PECAH_SERI!N8,IF(AND(D8="Aktif",H8<3),"Menunggu "&(3-H8)&" hakim","")) | P8: =JURI!AC8 | Q8: =JURI!AD8 | R8: =JURI!AE8 | S8: =JURI!AF8 | T8: =JURI!AG8
A9: 4 | B9: KELANTAN | C9: SHE ATE | D9: Aktif | E9: =IF(HAKIM_H1!$Q9="LENGKAP",HAKIM_H1!$P9,"") | F9: =IF(HAKIM_H2!$Q9="LENGKAP",HAKIM_H2!$P9,"") | G9: =IF(HAKIM_H3!$Q9="LENGKAP",HAKIM_H3!$P9,"") | H9: =COUNT(E9:G9) | I9: =IF(H9=3,ROUND(AVERAGE(E9:G9),2),"") | J9: =IF(D9="BATAL",0,IF(D9="Aktif",I9,"")) | K9: =IF(H9=3,IF(AVERAGE(E9:G9)>0,ROUND((MAX(E9:G9)-MIN(E9:G9))/AVERAGE(E9:G9)*100,0),0),"") | L9: =IF(K9="","",IF(K9>20,"SEMAK: sisihan "&K9&"%","")) | M9: =IF(D9="Tarik diri","TARIK DIRI",IF(D9="BATAL","BATAL",IF(PECAH_SERI!M9="","",PECAH_SERI!M9))) | N9: =IF(PECAH_SERI!N9<>"",PECAH_SERI!N9,IF(AND(D9="Aktif",H9<3),"Menunggu "&(3-H9)&" hakim","")) | P9: =JURI!AC9 | Q9: =JURI!AD9 | R9: =JURI!AE9 | S9: =JURI!AF9 | T9: =JURI!AG9
A10: 5 | B10: TERENGGANU | C10: WIRAWATI CYBER | D10: Aktif | E10: =IF(HAKIM_H1!$Q10="LENGKAP",HAKIM_H1!$P10,"") | F10: =IF(HAKIM_H2!$Q10="LENGKAP",HAKIM_H2!$P10,"") | G10: =IF(HAKIM_H3!$Q10="LENGKAP",HAKIM_H3!$P10,"") | H10: =COUNT(E10:G10) | I10: =IF(H10=3,ROUND(AVERAGE(E10:G10),2),"") | J10: =IF(D10="BATAL",0,IF(D10="Aktif",I10,"")) | K10: =IF(H10=3,IF(AVERAGE(E10:G10)>0,ROUND((MAX(E10:G10)-MIN(E10:G10))/AVERAGE(E10:G10)*100,0),0),"") | L10: =IF(K10="","",IF(K10>20,"SEMAK: sisihan "&K10&"%","")) | M10: =IF(D10="Tarik diri","TARIK DIRI",IF(D10="BATAL","BATAL",IF(PECAH_SERI!M10="","",PECAH_SERI!M10))) | N10: =IF(PECAH_SERI!N10<>"",PECAH_SERI!N10,IF(AND(D10="Aktif",H10<3),"Menunggu "&(3-H10)&" hakim","")) | P10: =JURI!AC10 | Q10: =JURI!AD10 | R10: =JURI!AE10 | S10: =JURI!AF10 | T10: =JURI!AG10
A11: 6 | B11: PAHANG | C11: YH SRIKANDI | D11: Aktif | E11: =IF(HAKIM_H1!$Q11="LENGKAP",HAKIM_H1!$P11,"") | F11: =IF(HAKIM_H2!$Q11="LENGKAP",HAKIM_H2!$P11,"") | G11: =IF(HAKIM_H3!$Q11="LENGKAP",HAKIM_H3!$P11,"") | H11: =COUNT(E11:G11) | I11: =IF(H11=3,ROUND(AVERAGE(E11:G11),2),"") | J11: =IF(D11="BATAL",0,IF(D11="Aktif",I11,"")) | K11: =IF(H11=3,IF(AVERAGE(E11:G11)>0,ROUND((MAX(E11:G11)-MIN(E11:G11))/AVERAGE(E11:G11)*100,0),0),"") | L11: =IF(K11="","",IF(K11>20,"SEMAK: sisihan "&K11&"%","")) | M11: =IF(D11="Tarik diri","TARIK DIRI",IF(D11="BATAL","BATAL",IF(PECAH_SERI!M11="","",PECAH_SERI!M11))) | N11: =IF(PECAH_SERI!N11<>"",PECAH_SERI!N11,IF(AND(D11="Aktif",H11<3),"Menunggu "&(3-H11)&" hakim","")) | P11: =JURI!AC11 | Q11: =JURI!AD11 | R11: =JURI!AE11 | S11: =JURI!AF11 | T11: =JURI!AG11
A12: 7 | B12: NEGERI SEMBILAN | C12: WAGHIH TECHNOVA | D12: Aktif | E12: =IF(HAKIM_H1!$Q12="LENGKAP",HAKIM_H1!$P12,"") | F12: =IF(HAKIM_H2!$Q12="LENGKAP",HAKIM_H2!$P12,"") | G12: =IF(HAKIM_H3!$Q12="LENGKAP",HAKIM_H3!$P12,"") | H12: =COUNT(E12:G12) | I12: =IF(H12=3,ROUND(AVERAGE(E12:G12),2),"") | J12: =IF(D12="BATAL",0,IF(D12="Aktif",I12,"")) | K12: =IF(H12=3,IF(AVERAGE(E12:G12)>0,ROUND((MAX(E12:G12)-MIN(E12:G12))/AVERAGE(E12:G12)*100,0),0),"") | L12: =IF(K12="","",IF(K12>20,"SEMAK: sisihan "&K12&"%","")) | M12: =IF(D12="Tarik diri","TARIK DIRI",IF(D12="BATAL","BATAL",IF(PECAH_SERI!M12="","",PECAH_SERI!M12))) | N12: =IF(PECAH_SERI!N12<>"",PECAH_SERI!N12,IF(AND(D12="Aktif",H12<3),"Menunggu "&(3-H12)&" hakim","")) | P12: =JURI!AC12 | Q12: =JURI!AD12 | R12: =JURI!AE12 | S12: =JURI!AF12 | T12: =JURI!AG12
A13: 8 | B13: MELAKA | C13: TUN TEJA | D13: Aktif | E13: =IF(HAKIM_H1!$Q13="LENGKAP",HAKIM_H1!$P13,"") | F13: =IF(HAKIM_H2!$Q13="LENGKAP",HAKIM_H2!$P13,"") | G13: =IF(HAKIM_H3!$Q13="LENGKAP",HAKIM_H3!$P13,"") | H13: =COUNT(E13:G13) | I13: =IF(H13=3,ROUND(AVERAGE(E13:G13),2),"") | J13: =IF(D13="BATAL",0,IF(D13="Aktif",I13,"")) | K13: =IF(H13=3,IF(AVERAGE(E13:G13)>0,ROUND((MAX(E13:G13)-MIN(E13:G13))/AVERAGE(E13:G13)*100,0),0),"") | L13: =IF(K13="","",IF(K13>20,"SEMAK: sisihan "&K13&"%","")) | M13: =IF(D13="Tarik diri","TARIK DIRI",IF(D13="BATAL","BATAL",IF(PECAH_SERI!M13="","",PECAH_SERI!M13))) | N13: =IF(PECAH_SERI!N13<>"",PECAH_SERI!N13,IF(AND(D13="Aktif",H13<3),"Menunggu "&(3-H13)&" hakim","")) | P13: =JURI!AC13 | Q13: =JURI!AD13 | R13: =JURI!AE13 | S13: =JURI!AF13 | T13: =JURI!AG13
A14: 9 | B14: PERAK | C14: VORTEX | D14: Aktif | E14: =IF(HAKIM_H1!$Q14="LENGKAP",HAKIM_H1!$P14,"") | F14: =IF(HAKIM_H2!$Q14="LENGKAP",HAKIM_H2!$P14,"") | G14: =IF(HAKIM_H3!$Q14="LENGKAP",HAKIM_H3!$P14,"") | H14: =COUNT(E14:G14) | I14: =IF(H14=3,ROUND(AVERAGE(E14:G14),2),"") | J14: =IF(D14="BATAL",0,IF(D14="Aktif",I14,"")) | K14: =IF(H14=3,IF(AVERAGE(E14:G14)>0,ROUND((MAX(E14:G14)-MIN(E14:G14))/AVERAGE(E14:G14)*100,0),0),"") | L14: =IF(K14="","",IF(K14>20,"SEMAK: sisihan "&K14&"%","")) | M14: =IF(D14="Tarik diri","TARIK DIRI",IF(D14="BATAL","BATAL",IF(PECAH_SERI!M14="","",PECAH_SERI!M14))) | N14: =IF(PECAH_SERI!N14<>"",PECAH_SERI!N14,IF(AND(D14="Aktif",H14<3),"Menunggu "&(3-H14)&" hakim","")) | P14: =JURI!AC14 | Q14: =JURI!AD14 | R14: =JURI!AE14 | S14: =JURI!AF14 | T14: =JURI!AG14
A15: 10 | B15: SELANGOR | C15: BYTESYNC | D15: Aktif | E15: =IF(HAKIM_H1!$Q15="LENGKAP",HAKIM_H1!$P15,"") | F15: =IF(HAKIM_H2!$Q15="LENGKAP",HAKIM_H2!$P15,"") | G15: =IF(HAKIM_H3!$Q15="LENGKAP",HAKIM_H3!$P15,"") | H15: =COUNT(E15:G15) | I15: =IF(H15=3,ROUND(AVERAGE(E15:G15),2),"") | J15: =IF(D15="BATAL",0,IF(D15="Aktif",I15,"")) | K15: =IF(H15=3,IF(AVERAGE(E15:G15)>0,ROUND((MAX(E15:G15)-MIN(E15:G15))/AVERAGE(E15:G15)*100,0),0),"") | L15: =IF(K15="","",IF(K15>20,"SEMAK: sisihan "&K15&"%","")) | M15: =IF(D15="Tarik diri","TARIK DIRI",IF(D15="BATAL","BATAL",IF(PECAH_SERI!M15="","",PECAH_SERI!M15))) | N15: =IF(PECAH_SERI!N15<>"",PECAH_SERI!N15,IF(AND(D15="Aktif",H15<3),"Menunggu "&(3-H15)&" hakim","")) | P15: =JURI!AC15 | Q15: =JURI!AD15 | R15: =JURI!AE15 | S15: =JURI!AF15 | T15: =JURI!AG15
A16: 11 | B16: JOHOR | C16: DWI KARYA | D16: Aktif | E16: =IF(HAKIM_H1!$Q16="LENGKAP",HAKIM_H1!$P16,"") | F16: =IF(HAKIM_H2!$Q16="LENGKAP",HAKIM_H2!$P16,"") | G16: =IF(HAKIM_H3!$Q16="LENGKAP",HAKIM_H3!$P16,"") | H16: =COUNT(E16:G16) | I16: =IF(H16=3,ROUND(AVERAGE(E16:G16),2),"") | J16: =IF(D16="BATAL",0,IF(D16="Aktif",I16,"")) | K16: =IF(H16=3,IF(AVERAGE(E16:G16)>0,ROUND((MAX(E16:G16)-MIN(E16:G16))/AVERAGE(E16:G16)*100,0),0),"") | L16: =IF(K16="","",IF(K16>20,"SEMAK: sisihan "&K16&"%","")) | M16: =IF(D16="Tarik diri","TARIK DIRI",IF(D16="BATAL","BATAL",IF(PECAH_SERI!M16="","",PECAH_SERI!M16))) | N16: =IF(PECAH_SERI!N16<>"",PECAH_SERI!N16,IF(AND(D16="Aktif",H16<3),"Menunggu "&(3-H16)&" hakim","")) | P16: =JURI!AC16 | Q16: =JURI!AD16 | R16: =JURI!AE16 | S16: =JURI!AF16 | T16: =JURI!AG16
A17: 12 | B17: WILAYAH PERSEKUTUAN | C17: SRIKANDI ULTRA | D17: Aktif | E17: =IF(HAKIM_H1!$Q17="LENGKAP",HAKIM_H1!$P17,"") | F17: =IF(HAKIM_H2!$Q17="LENGKAP",HAKIM_H2!$P17,"") | G17: =IF(HAKIM_H3!$Q17="LENGKAP",HAKIM_H3!$P17,"") | H17: =COUNT(E17:G17) | I17: =IF(H17=3,ROUND(AVERAGE(E17:G17),2),"") | J17: =IF(D17="BATAL",0,IF(D17="Aktif",I17,"")) | K17: =IF(H17=3,IF(AVERAGE(E17:G17)>0,ROUND((MAX(E17:G17)-MIN(E17:G17))/AVERAGE(E17:G17)*100,0),0),"") | L17: =IF(K17="","",IF(K17>20,"SEMAK: sisihan "&K17&"%","")) | M17: =IF(D17="Tarik diri","TARIK DIRI",IF(D17="BATAL","BATAL",IF(PECAH_SERI!M17="","",PECAH_SERI!M17))) | N17: =IF(PECAH_SERI!N17<>"",PECAH_SERI!N17,IF(AND(D17="Aktif",H17<3),"Menunggu "&(3-H17)&" hakim","")) | P17: =JURI!AC17 | Q17: =JURI!AD17 | R17: =JURI!AE17 | S17: =JURI!AF17 | T17: =JURI!AG17
... A19: 14 | B19: SABAH | C19: BORNEO FRAME | D19: Aktif | E19: =IF(HAKIM_H1!$Q19="LENGKAP",HAKIM_H1!$P19,"") | F19: =IF(HAKIM_H2!$Q19="LENGKAP",HAKIM_H2!$P19,"") | G19: =IF(HAKIM_H3!$Q19="LENGKAP",HAKIM_H3!$P19,"") | H19: =COUNT(E19:G19) | I19: =IF(H19=3,ROUND(AVERAGE(E19:G19),2),"") | J19: =IF(D19="BATAL",0,IF(D19="Aktif",I19,"")) | K19: =IF(H19=3,IF(AVERAGE(E19:G19)>0,ROUND((MAX(E19:G19)-MIN(E19:G19))/AVERAGE(E19:G19)*100,0),0),"") | L19: =IF(K19="","",IF(K19>20,"SEMAK: sisihan "&K19&"%","")) | M19: =IF(D19="Tarik diri","TARIK DIRI",IF(D19="BATAL","BATAL",IF(PECAH_SERI!M19="","",PECAH_SERI!M19))) | N19: =IF(PECAH_SERI!N19<>"",PECAH_SERI!N19,IF(AND(D19="Aktif",H19<3),"Menunggu "&(3-H19)&" hakim","")) | P19: =JURI!AC19 | Q19: =JURI!AD19 | R19: =JURI!AE19 | S19: =JURI!AF19 | T19: =JURI!AG19
A21: PENGESAHAN (GP 15.6): markah akhir wajib dikira semula dan disahkan oleh DUA orang Urusetia Kehakiman
A22: Urusetia 1 (nama penuh) | H22: Tarikh dan masa
A23: Urusetia 2 (nama penuh) | H23: Tarikh dan masa
A24: Ketua Hakim (H1) mengesahkan | D24: Belum | H24: Seri penuh diputuskan panel | J24: Tidak berkenaan
A25: STATUS KEPUTUSAN | D25: =IF(COUNTIF(D6:D19,"Aktif")=0,"BELUM MUKTAMAD: tiada pasukan aktif",IF(COUNTIF(D6:D19,"Aktif")<>COUNTIFS(D6:D19,"Aktif",H6:H19,3),"BELUM MUKTAMAD: ada pasukan belum lengkap tiga hakim",IF(COUNTIF(SEMAKAN!E6:E19,"BEZA*")>0,"BELUM MUKTAMAD: kiraan semula BEZA, semak tab SEMAKAN",IF(OR(D22="",D23="",D22=D23),"BELUM MUKTAMAD: perlu dua nama Urusetia yang berbeza",IF(D24<>"Ya","BELUM MUKTAMAD: Ketua Hakim belum mengesahkan",IF(AND(COUNTIF(PECAH_SERI!N6:N19,"SERI*")>0,J24<>"Ya, direkod"),"BELUM MUKTAMAD: seri penuh belum diputuskan panel","MUKTAMAD: dikira semula dan disahkan dua urus setia"))))))

Sheet HAKIM_H1
A1: MARKAH HAKIM H1 | tampal daripada tab SALIN borang hakim berkenaan
A2: Tampal NILAI SAHAJA (Ctrl+Shift+V) dari A5:M18 borang hakim ke sel A6. Lajur N hingga Q dikira dan disemak automatik. Jangan taip di lajur biru.
A3: Hakim: H1 (Ketua Hakim)
A4: Maksimum | B4: 20 | C4: 15 | D4: 15 | E4: 10 | F4: 10 | G4: 10 | H4: 5 | I4: 10 | J4: 5 | K4: 3 | L4: 2
A5: Negeri | B5: Kreativiti | C5: Kandungan | D5: Canva | E5: AI | F5: CapCut | G5: Audio | H5: Etika | I5: Persembahan | J5: AURORA | K5: Penalti aset | L5: Penalti budi | M5: Jumlah akhir (rujukan hakim) | N5: Jumlah komponen | O5: Penalti | P5: JUMLAH HAKIM | Q5: Semakan
N6: =IF(COUNT(B6:J6)=9,SUM(B6:J6),"") | O6: =IF(N6="","",N(K6)+N(L6)) | P6: =IF(N6="","",MAX(0,N6-O6)) | Q6: =IF(KEPUTUSAN!$D6<>"Aktif","Dikecualikan",IF(COUNT(B6:J6)=0,"Belum ditampal",IF(A6<>KEPUTUSAN!$B6,"Negeri tidak sepadan",IF(OR(COUNT(B6:J6)<9,K6="",L6=""),"Tidak lengkap",IF(OR(SUMPRODUCT((B6:J6>$B$4:$J$4)*1)>0,SUMPRODUCT((B6:J6<0)*1)>0,K6>3,L6>2,K6<0,L6<0),"Melebihi had",IF(SUMPRODUCT((B6:J6<>INT(B6:J6))*1)>0,"Bukan nombor bulat",IF(N(M6)<>P6,"Jumlah rujukan tidak sepadan","LENGKAP")))))))
N7: =IF(COUNT(B7:J7)=9,SUM(B7:J7),"") | O7: =IF(N7="","",N(K7)+N(L7)) | P7: =IF(N7="","",MAX(0,N7-O7)) | Q7: =IF(KEPUTUSAN!$D7<>"Aktif","Dikecualikan",IF(COUNT(B7:J7)=0,"Belum ditampal",IF(A7<>KEPUTUSAN!$B7,"Negeri tidak sepadan",IF(OR(COUNT(B7:J7)<9,K7="",L7=""),"Tidak lengkap",IF(OR(SUMPRODUCT((B7:J7>$B$4:$J$4)*1)>0,SUMPRODUCT((B7:J7<0)*1)>0,K7>3,L7>2,K7<0,L7<0),"Melebihi had",IF(SUMPRODUCT((B7:J7<>INT(B7:J7))*1)>0,"Bukan nombor bulat",IF(N(M7)<>P7,"Jumlah rujukan tidak sepadan","LENGKAP")))))))
N8: =IF(COUNT(B8:J8)=9,SUM(B8:J8),"") | O8: =IF(N8="","",N(K8)+N(L8)) | P8: =IF(N8="","",MAX(0,N8-O8)) | Q8: =IF(KEPUTUSAN!$D8<>"Aktif","Dikecualikan",IF(COUNT(B8:J8)=0,"Belum ditampal",IF(A8<>KEPUTUSAN!$B8,"Negeri tidak sepadan",IF(OR(COUNT(B8:J8)<9,K8="",L8=""),"Tidak lengkap",IF(OR(SUMPRODUCT((B8:J8>$B$4:$J$4)*1)>0,SUMPRODUCT((B8:J8<0)*1)>0,K8>3,L8>2,K8<0,L8<0),"Melebihi had",IF(SUMPRODUCT((B8:J8<>INT(B8:J8))*1)>0,"Bukan nombor bulat",IF(N(M8)<>P8,"Jumlah rujukan tidak sepadan","LENGKAP")))))))
N9: =IF(COUNT(B9:J9)=9,SUM(B9:J9),"") | O9: =IF(N9="","",N(K9)+N(L9)) | P9: =IF(N9="","",MAX(0,N9-O9)) | Q9: =IF(KEPUTUSAN!$D9<>"Aktif","Dikecualikan",IF(COUNT(B9:J9)=0,"Belum ditampal",IF(A9<>KEPUTUSAN!$B9,"Negeri tidak sepadan",IF(OR(COUNT(B9:J9)<9,K9="",L9=""),"Tidak lengkap",IF(OR(SUMPRODUCT((B9:J9>$B$4:$J$4)*1)>0,SUMPRODUCT((B9:J9<0)*1)>0,K9>3,L9>2,K9<0,L9<0),"Melebihi had",IF(SUMPRODUCT((B9:J9<>INT(B9:J9))*1)>0,"Bukan nombor bulat",IF(N(M9)<>P9,"Jumlah rujukan tidak sepadan","LENGKAP")))))))
N10: =IF(COUNT(B10:J10)=9,SUM(B10:J10),"") | O10: =IF(N10="","",N(K10)+N(L10)) | P10: =IF(N10="","",MAX(0,N10-O10)) | Q10: =IF(KEPUTUSAN!$D10<>"Aktif","Dikecualikan",IF(COUNT(B10:J10)=0,"Belum ditampal",IF(A10<>KEPUTUSAN!$B10,"Negeri tidak sepadan",IF(OR(COUNT(B10:J10)<9,K10="",L10=""),"Tidak lengkap",IF(OR(SUMPRODUCT((B10:J10>$B$4:$J$4)*1)>0,SUMPRODUCT((B10:J10<0)*1)>0,K10>3,L10>2,K10<0,L10<0),"Melebihi had",IF(SUMPRODUCT((B10:J10<>INT(B10:J10))*1)>0,"Bukan nombor bulat",IF(N(M10)<>P10,"Jumlah rujukan tidak sepadan","LENGKAP")))))))
N11: =IF(COUNT(B11:J11)=9,SUM(B11:J11),"") | O11: =IF(N11="","",N(K11)+N(L11)) | P11: =IF(N11="","",MAX(0,N11-O11)) | Q11: =IF(KEPUTUSAN!$D11<>"Aktif","Dikecualikan",IF(COUNT(B11:J11)=0,"Belum ditampal",IF(A11<>KEPUTUSAN!$B11,"Negeri tidak sepadan",IF(OR(COUNT(B11:J11)<9,K11="",L11=""),"Tidak lengkap",IF(OR(SUMPRODUCT((B11:J11>$B$4:$J$4)*1)>0,SUMPRODUCT((B11:J11<0)*1)>0,K11>3,L11>2,K11<0,L11<0),"Melebihi had",IF(SUMPRODUCT((B11:J11<>INT(B11:J11))*1)>0,"Bukan nombor bulat",IF(N(M11)<>P11,"Jumlah rujukan tidak sepadan","LENGKAP")))))))
N12: =IF(COUNT(B12:J12)=9,SUM(B12:J12),"") | O12: =IF(N12="","",N(K12)+N(L12)) | P12: =IF(N12="","",MAX(0,N12-O12)) | Q12: =IF(KEPUTUSAN!$D12<>"Aktif","Dikecualikan",IF(COUNT(B12:J12)=0,"Belum ditampal",IF(A12<>KEPUTUSAN!$B12,"Negeri tidak sepadan",IF(OR(COUNT(B12:J12)<9,K12="",L12=""),"Tidak lengkap",IF(OR(SUMPRODUCT((B12:J12>$B$4:$J$4)*1)>0,SUMPRODUCT((B12:J12<0)*1)>0,K12>3,L12>2,K12<0,L12<0),"Melebihi had",IF(SUMPRODUCT((B12:J12<>INT(B12:J12))*1)>0,"Bukan nombor bulat",IF(N(M12)<>P12,"Jumlah rujukan tidak sepadan","LENGKAP")))))))
N13: =IF(COUNT(B13:J13)=9,SUM(B13:J13),"") | O13: =IF(N13="","",N(K13)+N(L13)) | P13: =IF(N13="","",MAX(0,N13-O13)) | Q13: =IF(KEPUTUSAN!$D13<>"Aktif","Dikecualikan",IF(COUNT(B13:J13)=0,"Belum ditampal",IF(A13<>KEPUTUSAN!$B13,"Negeri tidak sepadan",IF(OR(COUNT(B13:J13)<9,K13="",L13=""),"Tidak lengkap",IF(OR(SUMPRODUCT((B13:J13>$B$4:$J$4)*1)>0,SUMPRODUCT((B13:J13<0)*1)>0,K13>3,L13>2,K13<0,L13<0),"Melebihi had",IF(SUMPRODUCT((B13:J13<>INT(B13:J13))*1)>0,"Bukan nombor bulat",IF(N(M13)<>P13,"Jumlah rujukan tidak sepadan","LENGKAP")))))))
N14: =IF(COUNT(B14:J14)=9,SUM(B14:J14),"") | O14: =IF(N14="","",N(K14)+N(L14)) | P14: =IF(N14="","",MAX(0,N14-O14)) | Q14: =IF(KEPUTUSAN!$D14<>"Aktif","Dikecualikan",IF(COUNT(B14:J14)=0,"Belum ditampal",IF(A14<>KEPUTUSAN!$B14,"Negeri tidak sepadan",IF(OR(COUNT(B14:J14)<9,K14="",L14=""),"Tidak lengkap",IF(OR(SUMPRODUCT((B14:J14>$B$4:$J$4)*1)>0,SUMPRODUCT((B14:J14<0)*1)>0,K14>3,L14>2,K14<0,L14<0),"Melebihi had",IF(SUMPRODUCT((B14:J14<>INT(B14:J14))*1)>0,"Bukan nombor bulat",IF(N(M14)<>P14,"Jumlah rujukan tidak sepadan","LENGKAP")))))))
N15: =IF(COUNT(B15:J15)=9,SUM(B15:J15),"") | O15: =IF(N15="","",N(K15)+N(L15)) | P15: =IF(N15="","",MAX(0,N15-O15)) | Q15: =IF(KEPUTUSAN!$D15<>"Aktif","Dikecualikan",IF(COUNT(B15:J15)=0,"Belum ditampal",IF(A15<>KEPUTUSAN!$B15,"Negeri tidak sepadan",IF(OR(COUNT(B15:J15)<9,K15="",L15=""),"Tidak lengkap",IF(OR(SUMPRODUCT((B15:J15>$B$4:$J$4)*1)>0,SUMPRODUCT((B15:J15<0)*1)>0,K15>3,L15>2,K15<0,L15<0),"Melebihi had",IF(SUMPRODUCT((B15:J15<>INT(B15:J15))*1)>0,"Bukan nombor bulat",IF(N(M15)<>P15,"Jumlah rujukan tidak sepadan","LENGKAP")))))))
N16: =IF(COUNT(B16:J16)=9,SUM(B16:J16),"") | O16: =IF(N16="","",N(K16)+N(L16)) | P16: =IF(N16="","",MAX(0,N16-O16)) | Q16: =IF(KEPUTUSAN!$D16<>"Aktif","Dikecualikan",IF(COUNT(B16:J16)=0,"Belum ditampal",IF(A16<>KEPUTUSAN!$B16,"Negeri tidak sepadan",IF(OR(COUNT(B16:J16)<9,K16="",L16=""),"Tidak lengkap",IF(OR(SUMPRODUCT((B16:J16>$B$4:$J$4)*1)>0,SUMPRODUCT((B16:J16<0)*1)>0,K16>3,L16>2,K16<0,L16<0),"Melebihi had",IF(SUMPRODUCT((B16:J16<>INT(B16:J16))*1)>0,"Bukan nombor bulat",IF(N(M16)<>P16,"Jumlah rujukan tidak sepadan","LENGKAP")))))))
N17: =IF(COUNT(B17:J17)=9,SUM(B17:J17),"") | O17: =IF(N17="","",N(K17)+N(L17)) | P17: =IF(N17="","",MAX(0,N17-O17)) | Q17: =IF(KEPUTUSAN!$D17<>"Aktif","Dikecualikan",IF(COUNT(B17:J17)=0,"Belum ditampal",IF(A17<>KEPUTUSAN!$B17,"Negeri tidak sepadan",IF(OR(COUNT(B17:J17)<9,K17="",L17=""),"Tidak lengkap",IF(OR(SUMPRODUCT((B17:J17>$B$4:$J$4)*1)>0,SUMPRODUCT((B17:J17<0)*1)>0,K17>3,L17>2,K17<0,L17<0),"Melebihi had",IF(SUMPRODUCT((B17:J17<>INT(B17:J17))*1)>0,"Bukan nombor bulat",IF(N(M17)<>P17,"Jumlah rujukan tidak sepadan","LENGKAP")))))))
... N19: =IF(COUNT(B19:J19)=9,SUM(B19:J19),"") | O19: =IF(N19="","",N(K19)+N(L19)) | P19: =IF(N19="","",MAX(0,N19-O19)) | Q19: =IF(KEPUTUSAN!$D19<>"Aktif","Dikecualikan",IF(COUNT(B19:J19)=0,"Belum ditampal",IF(A19<>KEPUTUSAN!$B19,"Negeri tidak sepadan",IF(OR(COUNT(B19:J19)<9,K19="",L19=""),"Tidak lengkap",IF(OR(SUMPRODUCT((B19:J19>$B$4:$J$4)*1)>0,SUMPRODUCT((B19:J19<0)*1)>0,K19>3,L19>2,K19<0,L19<0),"Melebihi had",IF(SUMPRODUCT((B19:J19<>INT(B19:J19))*1)>0,"Bukan nombor bulat",IF(N(M19)<>P19,"Jumlah rujukan tidak sepadan","LENGKAP")))))))

Sheet HAKIM_H2
A1: MARKAH HAKIM H2 | tampal daripada tab SALIN borang hakim berkenaan
A2: Tampal NILAI SAHAJA (Ctrl+Shift+V) dari A5:M18 borang hakim ke sel A6. Lajur N hingga Q dikira dan disemak automatik. Jangan taip di lajur biru.
A3: Hakim: H2 (Panel Hakim)
A4: Maksimum | B4: 20 | C4: 15 | D4: 15 | E4: 10 | F4: 10 | G4: 10 | H4: 5 | I4: 10 | J4: 5 | K4: 3 | L4: 2
A5: Negeri | B5: Kreativiti | C5: Kandungan | D5: Canva | E5: AI | F5: CapCut | G5: Audio | H5: Etika | I5: Persembahan | J5: AURORA | K5: Penalti aset | L5: Penalti budi | M5: Jumlah akhir (rujukan hakim) | N5: Jumlah komponen | O5: Penalti | P5: JUMLAH HAKIM | Q5: Semakan
N6: =IF(COUNT(B6:J6)=9,SUM(B6:J6),"") | O6: =IF(N6="","",N(K6)+N(L6)) | P6: =IF(N6="","",MAX(0,N6-O6)) | Q6: =IF(KEPUTUSAN!$D6<>"Aktif","Dikecualikan",IF(COUNT(B6:J6)=0,"Belum ditampal",IF(A6<>KEPUTUSAN!$B6,"Negeri tidak sepadan",IF(OR(COUNT(B6:J6)<9,K6="",L6=""),"Tidak lengkap",IF(OR(SUMPRODUCT((B6:J6>$B$4:$J$4)*1)>0,SUMPRODUCT((B6:J6<0)*1)>0,K6>3,L6>2,K6<0,L6<0),"Melebihi had",IF(SUMPRODUCT((B6:J6<>INT(B6:J6))*1)>0,"Bukan nombor bulat",IF(N(M6)<>P6,"Jumlah rujukan tidak sepadan","LENGKAP")))))))
N7: =IF(COUNT(B7:J7)=9,SUM(B7:J7),"") | O7: =IF(N7="","",N(K7)+N(L7)) | P7: =IF(N7="","",MAX(0,N7-O7)) | Q7: =IF(KEPUTUSAN!$D7<>"Aktif","Dikecualikan",IF(COUNT(B7:J7)=0,"Belum ditampal",IF(A7<>KEPUTUSAN!$B7,"Negeri tidak sepadan",IF(OR(COUNT(B7:J7)<9,K7="",L7=""),"Tidak lengkap",IF(OR(SUMPRODUCT((B7:J7>$B$4:$J$4)*1)>0,SUMPRODUCT((B7:J7<0)*1)>0,K7>3,L7>2,K7<0,L7<0),"Melebihi had",IF(SUMPRODUCT((B7:J7<>INT(B7:J7))*1)>0,"Bukan nombor bulat",IF(N(M7)<>P7,"Jumlah rujukan tidak sepadan","LENGKAP")))))))
N8: =IF(COUNT(B8:J8)=9,SUM(B8:J8),"") | O8: =IF(N8="","",N(K8)+N(L8)) | P8: =IF(N8="","",MAX(0,N8-O8)) | Q8: =IF(KEPUTUSAN!$D8<>"Aktif","Dikecualikan",IF(COUNT(B8:J8)=0,"Belum ditampal",IF(A8<>KEPUTUSAN!$B8,"Negeri tidak sepadan",IF(OR(COUNT(B8:J8)<9,K8="",L8=""),"Tidak lengkap",IF(OR(SUMPRODUCT((B8:J8>$B$4:$J$4)*1)>0,SUMPRODUCT((B8:J8<0)*1)>0,K8>3,L8>2,K8<0,L8<0),"Melebihi had",IF(SUMPRODUCT((B8:J8<>INT(B8:J8))*1)>0,"Bukan nombor bulat",IF(N(M8)<>P8,"Jumlah rujukan tidak sepadan","LENGKAP")))))))
N9: =IF(COUNT(B9:J9)=9,SUM(B9:J9),"") | O9: =IF(N9="","",N(K9)+N(L9)) | P9: =IF(N9="","",MAX(0,N9-O9)) | Q9: =IF(KEPUTUSAN!$D9<>"Aktif","Dikecualikan",IF(COUNT(B9:J9)=0,"Belum ditampal",IF(A9<>KEPUTUSAN!$B9,"Negeri tidak sepadan",IF(OR(COUNT(B9:J9)<9,K9="",L9=""),"Tidak lengkap",IF(OR(SUMPRODUCT((B9:J9>$B$4:$J$4)*1)>0,SUMPRODUCT((B9:J9<0)*1)>0,K9>3,L9>2,K9<0,L9<0),"Melebihi had",IF(SUMPRODUCT((B9:J9<>INT(B9:J9))*1)>0,"Bukan nombor bulat",IF(N(M9)<>P9,"Jumlah rujukan tidak sepadan","LENGKAP")))))))
N10: =IF(COUNT(B10:J10)=9,SUM(B10:J10),"") | O10: =IF(N10="","",N(K10)+N(L10)) | P10: =IF(N10="","",MAX(0,N10-O10)) | Q10: =IF(KEPUTUSAN!$D10<>"Aktif","Dikecualikan",IF(COUNT(B10:J10)=0,"Belum ditampal",IF(A10<>KEPUTUSAN!$B10,"Negeri tidak sepadan",IF(OR(COUNT(B10:J10)<9,K10="",L10=""),"Tidak lengkap",IF(OR(SUMPRODUCT((B10:J10>$B$4:$J$4)*1)>0,SUMPRODUCT((B10:J10<0)*1)>0,K10>3,L10>2,K10<0,L10<0),"Melebihi had",IF(SUMPRODUCT((B10:J10<>INT(B10:J10))*1)>0,"Bukan nombor bulat",IF(N(M10)<>P10,"Jumlah rujukan tidak sepadan","LENGKAP")))))))
N11: =IF(COUNT(B11:J11)=9,SUM(B11:J11),"") | O11: =IF(N11="","",N(K11)+N(L11)) | P11: =IF(N11="","",MAX(0,N11-O11)) | Q11: =IF(KEPUTUSAN!$D11<>"Aktif","Dikecualikan",IF(COUNT(B11:J11)=0,"Belum ditampal",IF(A11<>KEPUTUSAN!$B11,"Negeri tidak sepadan",IF(OR(COUNT(B11:J11)<9,K11="",L11=""),"Tidak lengkap",IF(OR(SUMPRODUCT((B11:J11>$B$4:$J$4)*1)>0,SUMPRODUCT((B11:J11<0)*1)>0,K11>3,L11>2,K11<0,L11<0),"Melebihi had",IF(SUMPRODUCT((B11:J11<>INT(B11:J11))*1)>0,"Bukan nombor bulat",IF(N(M11)<>P11,"Jumlah rujukan tidak sepadan","LENGKAP")))))))
N12: =IF(COUNT(B12:J12)=9,SUM(B12:J12),"") | O12: =IF(N12="","",N(K12)+N(L12)) | P12: =IF(N12="","",MAX(0,N12-O12)) | Q12: =IF(KEPUTUSAN!$D12<>"Aktif","Dikecualikan",IF(COUNT(B12:J12)=0,"Belum ditampal",IF(A12<>KEPUTUSAN!$B12,"Negeri tidak sepadan",IF(OR(COUNT(B12:J12)<9,K12="",L12=""),"Tidak lengkap",IF(OR(SUMPRODUCT((B12:J12>$B$4:$J$4)*1)>0,SUMPRODUCT((B12:J12<0)*1)>0,K12>3,L12>2,K12<0,L12<0),"Melebihi had",IF(SUMPRODUCT((B12:J12<>INT(B12:J12))*1)>0,"Bukan nombor bulat",IF(N(M12)<>P12,"Jumlah rujukan tidak sepadan","LENGKAP")))))))
N13: =IF(COUNT(B13:J13)=9,SUM(B13:J13),"") | O13: =IF(N13="","",N(K13)+N(L13)) | P13: =IF(N13="","",MAX(0,N13-O13)) | Q13: =IF(KEPUTUSAN!$D13<>"Aktif","Dikecualikan",IF(COUNT(B13:J13)=0,"Belum ditampal",IF(A13<>KEPUTUSAN!$B13,"Negeri tidak sepadan",IF(OR(COUNT(B13:J13)<9,K13="",L13=""),"Tidak lengkap",IF(OR(SUMPRODUCT((B13:J13>$B$4:$J$4)*1)>0,SUMPRODUCT((B13:J13<0)*1)>0,K13>3,L13>2,K13<0,L13<0),"Melebihi had",IF(SUMPRODUCT((B13:J13<>INT(B13:J13))*1)>0,"Bukan nombor bulat",IF(N(M13)<>P13,"Jumlah rujukan tidak sepadan","LENGKAP")))))))
N14: =IF(COUNT(B14:J14)=9,SUM(B14:J14),"") | O14: =IF(N14="","",N(K14)+N(L14)) | P14: =IF(N14="","",MAX(0,N14-O14)) | Q14: =IF(KEPUTUSAN!$D14<>"Aktif","Dikecualikan",IF(COUNT(B14:J14)=0,"Belum ditampal",IF(A14<>KEPUTUSAN!$B14,"Negeri tidak sepadan",IF(OR(COUNT(B14:J14)<9,K14="",L14=""),"Tidak lengkap",IF(OR(SUMPRODUCT((B14:J14>$B$4:$J$4)*1)>0,SUMPRODUCT((B14:J14<0)*1)>0,K14>3,L14>2,K14<0,L14<0),"Melebihi had",IF(SUMPRODUCT((B14:J14<>INT(B14:J14))*1)>0,"Bukan nombor bulat",IF(N(M14)<>P14,"Jumlah rujukan tidak sepadan","LENGKAP")))))))
N15: =IF(COUNT(B15:J15)=9,SUM(B15:J15),"") | O15: =IF(N15="","",N(K15)+N(L15)) | P15: =IF(N15="","",MAX(0,N15-O15)) | Q15: =IF(KEPUTUSAN!$D15<>"Aktif","Dikecualikan",IF(COUNT(B15:J15)=0,"Belum ditampal",IF(A15<>KEPUTUSAN!$B15,"Negeri tidak sepadan",IF(OR(COUNT(B15:J15)<9,K15="",L15=""),"Tidak lengkap",IF(OR(SUMPRODUCT((B15:J15>$B$4:$J$4)*1)>0,SUMPRODUCT((B15:J15<0)*1)>0,K15>3,L15>2,K15<0,L15<0),"Melebihi had",IF(SUMPRODUCT((B15:J15<>INT(B15:J15))*1)>0,"Bukan nombor bulat",IF(N(M15)<>P15,"Jumlah rujukan tidak sepadan","LENGKAP")))))))
N16: =IF(COUNT(B16:J16)=9,SUM(B16:J16),"") | O16: =IF(N16="","",N(K16)+N(L16)) | P16: =IF(N16="","",MAX(0,N16-O16)) | Q16: =IF(KEPUTUSAN!$D16<>"Aktif","Dikecualikan",IF(COUNT(B16:J16)=0,"Belum ditampal",IF(A16<>KEPUTUSAN!$B16,"Negeri tidak sepadan",IF(OR(COUNT(B16:J16)<9,K16="",L16=""),"Tidak lengkap",IF(OR(SUMPRODUCT((B16:J16>$B$4:$J$4)*1)>0,SUMPRODUCT((B16:J16<0)*1)>0,K16>3,L16>2,K16<0,L16<0),"Melebihi had",IF(SUMPRODUCT((B16:J16<>INT(B16:J16))*1)>0,"Bukan nombor bulat",IF(N(M16)<>P16,"Jumlah rujukan tidak sepadan","LENGKAP")))))))
N17: =IF(COUNT(B17:J17)=9,SUM(B17:J17),"") | O17: =IF(N17="","",N(K17)+N(L17)) | P17: =IF(N17="","",MAX(0,N17-O17)) | Q17: =IF(KEPUTUSAN!$D17<>"Aktif","Dikecualikan",IF(COUNT(B17:J17)=0,"Belum ditampal",IF(A17<>KEPUTUSAN!$B17,"Negeri tidak sepadan",IF(OR(COUNT(B17:J17)<9,K17="",L17=""),"Tidak lengkap",IF(OR(SUMPRODUCT((B17:J17>$B$4:$J$4)*1)>0,SUMPRODUCT((B17:J17<0)*1)>0,K17>3,L17>2,K17<0,L17<0),"Melebihi had",IF(SUMPRODUCT((B17:J17<>INT(B17:J17))*1)>0,"Bukan nombor bulat",IF(N(M17)<>P17,"Jumlah rujukan tidak sepadan","LENGKAP")))))))
... N19: =IF(COUNT(B19:J19)=9,SUM(B19:J19),"") | O19: =IF(N19="","",N(K19)+N(L19)) | P19: =IF(N19="","",MAX(0,N19-O19)) | Q19: =IF(KEPUTUSAN!$D19<>"Aktif","Dikecualikan",IF(COUNT(B19:J19)=0,"Belum ditampal",IF(A19<>KEPUTUSAN!$B19,"Negeri tidak sepadan",IF(OR(COUNT(B19:J19)<9,K19="",L19=""),"Tidak lengkap",IF(OR(SUMPRODUCT((B19:J19>$B$4:$J$4)*1)>0,SUMPRODUCT((B19:J19<0)*1)>0,K19>3,L19>2,K19<0,L19<0),"Melebihi had",IF(SUMPRODUCT((B19:J19<>INT(B19:J19))*1)>0,"Bukan nombor bulat",IF(N(M19)<>P19,"Jumlah rujukan tidak sepadan","LENGKAP")))))))

Sheet HAKIM_H3
A1: MARKAH HAKIM H3 | tampal daripada tab SALIN borang hakim berkenaan
A2: Tampal NILAI SAHAJA (Ctrl+Shift+V) dari A5:M18 borang hakim ke sel A6. Lajur N hingga Q dikira dan disemak automatik. Jangan taip di lajur biru.
A3: Hakim: H3 (Panel Hakim)
A4: Maksimum | B4: 20 | C4: 15 | D4: 15 | E4: 10 | F4: 10 | G4: 10 | H4: 5 | I4: 10 | J4: 5 | K4: 3 | L4: 2
A5: Negeri | B5: Kreativiti | C5: Kandungan | D5: Canva | E5: AI | F5: CapCut | G5: Audio | H5: Etika | I5: Persembahan | J5: AURORA | K5: Penalti aset | L5: Penalti budi | M5: Jumlah akhir (rujukan hakim) | N5: Jumlah komponen | O5: Penalti | P5: JUMLAH HAKIM | Q5: Semakan
N6: =IF(COUNT(B6:J6)=9,SUM(B6:J6),"") | O6: =IF(N6="","",N(K6)+N(L6)) | P6: =IF(N6="","",MAX(0,N6-O6)) | Q6: =IF(KEPUTUSAN!$D6<>"Aktif","Dikecualikan",IF(COUNT(B6:J6)=0,"Belum ditampal",IF(A6<>KEPUTUSAN!$B6,"Negeri tidak sepadan",IF(OR(COUNT(B6:J6)<9,K6="",L6=""),"Tidak lengkap",IF(OR(SUMPRODUCT((B6:J6>$B$4:$J$4)*1)>0,SUMPRODUCT((B6:J6<0)*1)>0,K6>3,L6>2,K6<0,L6<0),"Melebihi had",IF(SUMPRODUCT((B6:J6<>INT(B6:J6))*1)>0,"Bukan nombor bulat",IF(N(M6)<>P6,"Jumlah rujukan tidak sepadan","LENGKAP")))))))
N7: =IF(COUNT(B7:J7)=9,SUM(B7:J7),"") | O7: =IF(N7="","",N(K7)+N(L7)) | P7: =IF(N7="","",MAX(0,N7-O7)) | Q7: =IF(KEPUTUSAN!$D7<>"Aktif","Dikecualikan",IF(COUNT(B7:J7)=0,"Belum ditampal",IF(A7<>KEPUTUSAN!$B7,"Negeri tidak sepadan",IF(OR(COUNT(B7:J7)<9,K7="",L7=""),"Tidak lengkap",IF(OR(SUMPRODUCT((B7:J7>$B$4:$J$4)*1)>0,SUMPRODUCT((B7:J7<0)*1)>0,K7>3,L7>2,K7<0,L7<0),"Melebihi had",IF(SUMPRODUCT((B7:J7<>INT(B7:J7))*1)>0,"Bukan nombor bulat",IF(N(M7)<>P7,"Jumlah rujukan tidak sepadan","LENGKAP")))))))
N8: =IF(COUNT(B8:J8)=9,SUM(B8:J8),"") | O8: =IF(N8="","",N(K8)+N(L8)) | P8: =IF(N8="","",MAX(0,N8-O8)) | Q8: =IF(KEPUTUSAN!$D8<>"Aktif","Dikecualikan",IF(COUNT(B8:J8)=0,"Belum ditampal",IF(A8<>KEPUTUSAN!$B8,"Negeri tidak sepadan",IF(OR(COUNT(B8:J8)<9,K8="",L8=""),"Tidak lengkap",IF(OR(SUMPRODUCT((B8:J8>$B$4:$J$4)*1)>0,SUMPRODUCT((B8:J8<0)*1)>0,K8>3,L8>2,K8<0,L8<0),"Melebihi had",IF(SUMPRODUCT((B8:J8<>INT(B8:J8))*1)>0,"Bukan nombor bulat",IF(N(M8)<>P8,"Jumlah rujukan tidak sepadan","LENGKAP")))))))
N9: =IF(COUNT(B9:J9)=9,SUM(B9:J9),"") | O9: =IF(N9="","",N(K9)+N(L9)) | P9: =IF(N9="","",MAX(0,N9-O9)) | Q9: =IF(KEPUTUSAN!$D9<>"Aktif","Dikecualikan",IF(COUNT(B9:J9)=0,"Belum ditampal",IF(A9<>KEPUTUSAN!$B9,"Negeri tidak sepadan",IF(OR(COUNT(B9:J9)<9,K9="",L9=""),"Tidak lengkap",IF(OR(SUMPRODUCT((B9:J9>$B$4:$J$4)*1)>0,SUMPRODUCT((B9:J9<0)*1)>0,K9>3,L9>2,K9<0,L9<0),"Melebihi had",IF(SUMPRODUCT((B9:J9<>INT(B9:J9))*1)>0,"Bukan nombor bulat",IF(N(M9)<>P9,"Jumlah rujukan tidak sepadan","LENGKAP")))))))
N10: =IF(COUNT(B10:J10)=9,SUM(B10:J10),"") | O10: =IF(N10="","",N(K10)+N(L10)) | P10: =IF(N10="","",MAX(0,N10-O10)) | Q10: =IF(KEPUTUSAN!$D10<>"Aktif","Dikecualikan",IF(COUNT(B10:J10)=0,"Belum ditampal",IF(A10<>KEPUTUSAN!$B10,"Negeri tidak sepadan",IF(OR(COUNT(B10:J10)<9,K10="",L10=""),"Tidak lengkap",IF(OR(SUMPRODUCT((B10:J10>$B$4:$J$4)*1)>0,SUMPRODUCT((B10:J10<0)*1)>0,K10>3,L10>2,K10<0,L10<0),"Melebihi had",IF(SUMPRODUCT((B10:J10<>INT(B10:J10))*1)>0,"Bukan nombor bulat",IF(N(M10)<>P10,"Jumlah rujukan tidak sepadan","LENGKAP")))))))
N11: =IF(COUNT(B11:J11)=9,SUM(B11:J11),"") | O11: =IF(N11="","",N(K11)+N(L11)) | P11: =IF(N11="","",MAX(0,N11-O11)) | Q11: =IF(KEPUTUSAN!$D11<>"Aktif","Dikecualikan",IF(COUNT(B11:J11)=0,"Belum ditampal",IF(A11<>KEPUTUSAN!$B11,"Negeri tidak sepadan",IF(OR(COUNT(B11:J11)<9,K11="",L11=""),"Tidak lengkap",IF(OR(SUMPRODUCT((B11:J11>$B$4:$J$4)*1)>0,SUMPRODUCT((B11:J11<0)*1)>0,K11>3,L11>2,K11<0,L11<0),"Melebihi had",IF(SUMPRODUCT((B11:J11<>INT(B11:J11))*1)>0,"Bukan nombor bulat",IF(N(M11)<>P11,"Jumlah rujukan tidak sepadan","LENGKAP")))))))
N12: =IF(COUNT(B12:J12)=9,SUM(B12:J12),"") | O12: =IF(N12="","",N(K12)+N(L12)) | P12: =IF(N12="","",MAX(0,N12-O12)) | Q12: =IF(KEPUTUSAN!$D12<>"Aktif","Dikecualikan",IF(COUNT(B12:J12)=0,"Belum ditampal",IF(A12<>KEPUTUSAN!$B12,"Negeri tidak sepadan",IF(OR(COUNT(B12:J12)<9,K12="",L12=""),"Tidak lengkap",IF(OR(SUMPRODUCT((B12:J12>$B$4:$J$4)*1)>0,SUMPRODUCT((B12:J12<0)*1)>0,K12>3,L12>2,K12<0,L12<0),"Melebihi had",IF(SUMPRODUCT((B12:J12<>INT(B12:J12))*1)>0,"Bukan nombor bulat",IF(N(M12)<>P12,"Jumlah rujukan tidak sepadan","LENGKAP")))))))
N13: =IF(COUNT(B13:J13)=9,SUM(B13:J13),"") | O13: =IF(N13="","",N(K13)+N(L13)) | P13: =IF(N13="","",MAX(0,N13-O13)) | Q13: =IF(KEPUTUSAN!$D13<>"Aktif","Dikecualikan",IF(COUNT(B13:J13)=0,"Belum ditampal",IF(A13<>KEPUTUSAN!$B13,"Negeri tidak sepadan",IF(OR(COUNT(B13:J13)<9,K13="",L13=""),"Tidak lengkap",IF(OR(SUMPRODUCT((B13:J13>$B$4:$J$4)*1)>0,SUMPRODUCT((B13:J13<0)*1)>0,K13>3,L13>2,K13<0,L13<0),"Melebihi had",IF(SUMPRODUCT((B13:J13<>INT(B13:J13))*1)>0,"Bukan nombor bulat",IF(N(M13)<>P13,"Jumlah rujukan tidak sepadan","LENGKAP")))))))
N14: =IF(COUNT(B14:J14)=9,SUM(B14:J14),"") | O14: =IF(N14="","",N(K14)+N(L14)) | P14: =IF(N14="","",MAX(0,N14-O14)) | Q14: =IF(KEPUTUSAN!$D14<>"Aktif","Dikecualikan",IF(COUNT(B14:J14)=0,"Belum ditampal",IF(A14<>KEPUTUSAN!$B14,"Negeri tidak sepadan",IF(OR(COUNT(B14:J14)<9,K14="",L14=""),"Tidak lengkap",IF(OR(SUMPRODUCT((B14:J14>$B$4:$J$4)*1)>0,SUMPRODUCT((B14:J14<0)*1)>0,K14>3,L14>2,K14<0,L14<0),"Melebihi had",IF(SUMPRODUCT((B14:J14<>INT(B14:J14))*1)>0,"Bukan nombor bulat",IF(N(M14)<>P14,"Jumlah rujukan tidak sepadan","LENGKAP")))))))
N15: =IF(COUNT(B15:J15)=9,SUM(B15:J15),"") | O15: =IF(N15="","",N(K15)+N(L15)) | P15: =IF(N15="","",MAX(0,N15-O15)) | Q15: =IF(KEPUTUSAN!$D15<>"Aktif","Dikecualikan",IF(COUNT(B15:J15)=0,"Belum ditampal",IF(A15<>KEPUTUSAN!$B15,"Negeri tidak sepadan",IF(OR(COUNT(B15:J15)<9,K15="",L15=""),"Tidak lengkap",IF(OR(SUMPRODUCT((B15:J15>$B$4:$J$4)*1)>0,SUMPRODUCT((B15:J15<0)*1)>0,K15>3,L15>2,K15<0,L15<0),"Melebihi had",IF(SUMPRODUCT((B15:J15<>INT(B15:J15))*1)>0,"Bukan nombor bulat",IF(N(M15)<>P15,"Jumlah rujukan tidak sepadan","LENGKAP")))))))
N16: =IF(COUNT(B16:J16)=9,SUM(B16:J16),"") | O16: =IF(N16="","",N(K16)+N(L16)) | P16: =IF(N16="","",MAX(0,N16-O16)) | Q16: =IF(KEPUTUSAN!$D16<>"Aktif","Dikecualikan",IF(COUNT(B16:J16)=0,"Belum ditampal",IF(A16<>KEPUTUSAN!$B16,"Negeri tidak sepadan",IF(OR(COUNT(B16:J16)<9,K16="",L16=""),"Tidak lengkap",IF(OR(SUMPRODUCT((B16:J16>$B$4:$J$4)*1)>0,SUMPRODUCT((B16:J16<0)*1)>0,K16>3,L16>2,K16<0,L16<0),"Melebihi had",IF(SUMPRODUCT((B16:J16<>INT(B16:J16))*1)>0,"Bukan nombor bulat",IF(N(M16)<>P16,"Jumlah rujukan tidak sepadan","LENGKAP")))))))
N17: =IF(COUNT(B17:J17)=9,SUM(B17:J17),"") | O17: =IF(N17="","",N(K17)+N(L17)) | P17: =IF(N17="","",MAX(0,N17-O17)) | Q17: =IF(KEPUTUSAN!$D17<>"Aktif","Dikecualikan",IF(COUNT(B17:J17)=0,"Belum ditampal",IF(A17<>KEPUTUSAN!$B17,"Negeri tidak sepadan",IF(OR(COUNT(B17:J17)<9,K17="",L17=""),"Tidak lengkap",IF(OR(SUMPRODUCT((B17:J17>$B$4:$J$4)*1)>0,SUMPRODUCT((B17:J17<0)*1)>0,K17>3,L17>2,K17<0,L17<0),"Melebihi had",IF(SUMPRODUCT((B17:J17<>INT(B17:J17))*1)>0,"Bukan nombor bulat",IF(N(M17)<>P17,"Jumlah rujukan tidak sepadan","LENGKAP")))))))
... N19: =IF(COUNT(B19:J19)=9,SUM(B19:J19),"") | O19: =IF(N19="","",N(K19)+N(L19)) | P19: =IF(N19="","",MAX(0,N19-O19)) | Q19: =IF(KEPUTUSAN!$D19<>"Aktif","Dikecualikan",IF(COUNT(B19:J19)=0,"Belum ditampal",IF(A19<>KEPUTUSAN!$B19,"Negeri tidak sepadan",IF(OR(COUNT(B19:J19)<9,K19="",L19=""),"Tidak lengkap",IF(OR(SUMPRODUCT((B19:J19>$B$4:$J$4)*1)>0,SUMPRODUCT((B19:J19<0)*1)>0,K19>3,L19>2,K19<0,L19<0),"Melebihi had",IF(SUMPRODUCT((B19:J19<>INT(B19:J19))*1)>0,"Bukan nombor bulat",IF(N(M19)<>P19,"Jumlah rujukan tidak sepadan","LENGKAP")))))))

Sheet JURI
A1: MATRIKS JURI AWAM | 25 juri x 14 pasukan
A2: Tampal NILAI SAHAJA lajur JUMLAH (G9:G22) borang juri ke lajur juri berkenaan bermula baris 6. Nilai 3 hingga 30 (jumlah tiga aspek). Kosong = tidak mengundi. Sumbangan = jumlah / 30 x 4.
A5: Bil | B5: Negeri | C5: Pasukan | D5: Juri 01 | E5: Juri 02 | F5: Juri 03 | G5: Juri 04 | H5: Juri 05 | I5: Juri 06 | J5: Juri 07 | K5: Juri 08 | L5: Juri 09 | M5: Juri 10 | N5: Juri 11 | O5: Juri 12 | P5: Juri 13 | Q5: Juri 14 | R5: Juri 15 | S5: Juri 16 | T5: Juri 17 | U5: Juri 18 | V5: Juri 19 | W5: Juri 20 | X5: Juri 21 | Y5: Juri 22 | Z5: Juri 23 | AA5: Juri 24 | AB5: Juri 25 | AC5: Bil undi | AD5: SKOR JURI (maks 100) | AE5: Kelayakan anugerah | AF5: Kedudukan juri | AG5: Catatan
A6: 1 | B6: =KEPUTUSAN!B6 | C6: =KEPUTUSAN!C6 | AC6: =COUNT(D6:AB6) | AD6: =ROUND(SUM(D6:AB6)/30*4,4) | AE6: =IF(KEPUTUSAN!$D6<>"Aktif","Tidak aktif",IF(AC6>25,"Tidak layak: lebih 25 undi",IF(AC6<5,"Tidak layak: kurang 5 undi","LAYAK"))) | AF6: =IF(AE6="LAYAK",1+SUMPRODUCT(($AE$6:$AE$19="LAYAK")*($AD$6:$AD$19>AD6)),"") | AG6: =IF(AE6="LAYAK",IF(SUMPRODUCT(($AE$6:$AE$19="LAYAK")*($AD$6:$AD$19=AD6))>1,"SERI: jawatankuasa putuskan",""),"")
A7: 2 | B7: =KEPUTUSAN!B7 | C7: =KEPUTUSAN!C7 | AC7: =COUNT(D7:AB7) | AD7: =ROUND(SUM(D7:AB7)/30*4,4) | AE7: =IF(KEPUTUSAN!$D7<>"Aktif","Tidak aktif",IF(AC7>25,"Tidak layak: lebih 25 undi",IF(AC7<5,"Tidak layak: kurang 5 undi","LAYAK"))) | AF7: =IF(AE7="LAYAK",1+SUMPRODUCT(($AE$6:$AE$19="LAYAK")*($AD$6:$AD$19>AD7)),"") | AG7: =IF(AE7="LAYAK",IF(SUMPRODUCT(($AE$6:$AE$19="LAYAK")*($AD$6:$AD$19=AD7))>1,"SERI: jawatankuasa putuskan",""),"")
A8: 3 | B8: =KEPUTUSAN!B8 | C8: =KEPUTUSAN!C8 | AC8: =COUNT(D8:AB8) | AD8: =ROUND(SUM(D8:AB8)/30*4,4) | AE8: =IF(KEPUTUSAN!$D8<>"Aktif","Tidak aktif",IF(AC8>25,"Tidak layak: lebih 25 undi",IF(AC8<5,"Tidak layak: kurang 5 undi","LAYAK"))) | AF8: =IF(AE8="LAYAK",1+SUMPRODUCT(($AE$6:$AE$19="LAYAK")*($AD$6:$AD$19>AD8)),"") | AG8: =IF(AE8="LAYAK",IF(SUMPRODUCT(($AE$6:$AE$19="LAYAK")*($AD$6:$AD$19=AD8))>1,"SERI: jawatankuasa putuskan",""),"")
A9: 4 | B9: =KEPUTUSAN!B9 | C9: =KEPUTUSAN!C9 | AC9: =COUNT(D9:AB9) | AD9: =ROUND(SUM(D9:AB9)/30*4,4) | AE9: =IF(KEPUTUSAN!$D9<>"Aktif","Tidak aktif",IF(AC9>25,"Tidak layak: lebih 25 undi",IF(AC9<5,"Tidak layak: kurang 5 undi","LAYAK"))) | AF9: =IF(AE9="LAYAK",1+SUMPRODUCT(($AE$6:$AE$19="LAYAK")*($AD$6:$AD$19>AD9)),"") | AG9: =IF(AE9="LAYAK",IF(SUMPRODUCT(($AE$6:$AE$19="LAYAK")*($AD$6:$AD$19=AD9))>1,"SERI: jawatankuasa putuskan",""),"")
A10: 5 | B10: =KEPUTUSAN!B10 | C10: =KEPUTUSAN!C10 | AC10: =COUNT(D10:AB10) | AD10: =ROUND(SUM(D10:AB10)/30*4,4) | AE10: =IF(KEPUTUSAN!$D10<>"Aktif","Tidak aktif",IF(AC10>25,"Tidak layak: lebih 25 undi",IF(AC10<5,"Tidak layak: kurang 5 undi","LAYAK"))) | AF10: =IF(AE10="LAYAK",1+SUMPRODUCT(($AE$6:$AE$19="LAYAK")*($AD$6:$AD$19>AD10)),"") | AG10: =IF(AE10="LAYAK",IF(SUMPRODUCT(($AE$6:$AE$19="LAYAK")*($AD$6:$AD$19=AD10))>1,"SERI: jawatankuasa putuskan",""),"")
A11: 6 | B11: =KEPUTUSAN!B11 | C11: =KEPUTUSAN!C11 | AC11: =COUNT(D11:AB11) | AD11: =ROUND(SUM(D11:AB11)/30*4,4) | AE11: =IF(KEPUTUSAN!$D11<>"Aktif","Tidak aktif",IF(AC11>25,"Tidak layak: lebih 25 undi",IF(AC11<5,"Tidak layak: kurang 5 undi","LAYAK"))) | AF11: =IF(AE11="LAYAK",1+SUMPRODUCT(($AE$6:$AE$19="LAYAK")*($AD$6:$AD$19>AD11)),"") | AG11: =IF(AE11="LAYAK",IF(SUMPRODUCT(($AE$6:$AE$19="LAYAK")*($AD$6:$AD$19=AD11))>1,"SERI: jawatankuasa putuskan",""),"")
A12: 7 | B12: =KEPUTUSAN!B12 | C12: =KEPUTUSAN!C12 | AC12: =COUNT(D12:AB12) | AD12: =ROUND(SUM(D12:AB12)/30*4,4) | AE12: =IF(KEPUTUSAN!$D12<>"Aktif","Tidak aktif",IF(AC12>25,"Tidak layak: lebih 25 undi",IF(AC12<5,"Tidak layak: kurang 5 undi","LAYAK"))) | AF12: =IF(AE12="LAYAK",1+SUMPRODUCT(($AE$6:$AE$19="LAYAK")*($AD$6:$AD$19>AD12)),"") | AG12: =IF(AE12="LAYAK",IF(SUMPRODUCT(($AE$6:$AE$19="LAYAK")*($AD$6:$AD$19=AD12))>1,"SERI: jawatankuasa putuskan",""),"")
A13: 8 | B13: =KEPUTUSAN!B13 | C13: =KEPUTUSAN!C13 | AC13: =COUNT(D13:AB13) | AD13: =ROUND(SUM(D13:AB13)/30*4,4) | AE13: =IF(KEPUTUSAN!$D13<>"Aktif","Tidak aktif",IF(AC13>25,"Tidak layak: lebih 25 undi",IF(AC13<5,"Tidak layak: kurang 5 undi","LAYAK"))) | AF13: =IF(AE13="LAYAK",1+SUMPRODUCT(($AE$6:$AE$19="LAYAK")*($AD$6:$AD$19>AD13)),"") | AG13: =IF(AE13="LAYAK",IF(SUMPRODUCT(($AE$6:$AE$19="LAYAK")*($AD$6:$AD$19=AD13))>1,"SERI: jawatankuasa putuskan",""),"")
A14: 9 | B14: =KEPUTUSAN!B14 | C14: =KEPUTUSAN!C14 | AC14: =COUNT(D14:AB14) | AD14: =ROUND(SUM(D14:AB14)/30*4,4) | AE14: =IF(KEPUTUSAN!$D14<>"Aktif","Tidak aktif",IF(AC14>25,"Tidak layak: lebih 25 undi",IF(AC14<5,"Tidak layak: kurang 5 undi","LAYAK"))) | AF14: =IF(AE14="LAYAK",1+SUMPRODUCT(($AE$6:$AE$19="LAYAK")*($AD$6:$AD$19>AD14)),"") | AG14: =IF(AE14="LAYAK",IF(SUMPRODUCT(($AE$6:$AE$19="LAYAK")*($AD$6:$AD$19=AD14))>1,"SERI: jawatankuasa putuskan",""),"")
A15: 10 | B15: =KEPUTUSAN!B15 | C15: =KEPUTUSAN!C15 | AC15: =COUNT(D15:AB15) | AD15: =ROUND(SUM(D15:AB15)/30*4,4) | AE15: =IF(KEPUTUSAN!$D15<>"Aktif","Tidak aktif",IF(AC15>25,"Tidak layak: lebih 25 undi",IF(AC15<5,"Tidak layak: kurang 5 undi","LAYAK"))) | AF15: =IF(AE15="LAYAK",1+SUMPRODUCT(($AE$6:$AE$19="LAYAK")*($AD$6:$AD$19>AD15)),"") | AG15: =IF(AE15="LAYAK",IF(SUMPRODUCT(($AE$6:$AE$19="LAYAK")*($AD$6:$AD$19=AD15))>1,"SERI: jawatankuasa putuskan",""),"")
A16: 11 | B16: =KEPUTUSAN!B16 | C16: =KEPUTUSAN!C16 | AC16: =COUNT(D16:AB16) | AD16: =ROUND(SUM(D16:AB16)/30*4,4) | AE16: =IF(KEPUTUSAN!$D16<>"Aktif","Tidak aktif",IF(AC16>25,"Tidak layak: lebih 25 undi",IF(AC16<5,"Tidak layak: kurang 5 undi","LAYAK"))) | AF16: =IF(AE16="LAYAK",1+SUMPRODUCT(($AE$6:$AE$19="LAYAK")*($AD$6:$AD$19>AD16)),"") | AG16: =IF(AE16="LAYAK",IF(SUMPRODUCT(($AE$6:$AE$19="LAYAK")*($AD$6:$AD$19=AD16))>1,"SERI: jawatankuasa putuskan",""),"")
A17: 12 | B17: =KEPUTUSAN!B17 | C17: =KEPUTUSAN!C17 | AC17: =COUNT(D17:AB17) | AD17: =ROUND(SUM(D17:AB17)/30*4,4) | AE17: =IF(KEPUTUSAN!$D17<>"Aktif","Tidak aktif",IF(AC17>25,"Tidak layak: lebih 25 undi",IF(AC17<5,"Tidak layak: kurang 5 undi","LAYAK"))) | AF17: =IF(AE17="LAYAK",1+SUMPRODUCT(($AE$6:$AE$19="LAYAK")*($AD$6:$AD$19>AD17)),"") | AG17: =IF(AE17="LAYAK",IF(SUMPRODUCT(($AE$6:$AE$19="LAYAK")*($AD$6:$AD$19=AD17))>1,"SERI: jawatankuasa putuskan",""),"")
... A19: 14 | B19: =KEPUTUSAN!B19 | C19: =KEPUTUSAN!C19 | AC19: =COUNT(D19:AB19) | AD19: =ROUND(SUM(D19:AB19)/30*4,4) | AE19: =IF(KEPUTUSAN!$D19<>"Aktif","Tidak aktif",IF(AC19>25,"Tidak layak: lebih 25 undi",IF(AC19<5,"Tidak layak: kurang 5 undi","LAYAK"))) | AF19: =IF(AE19="LAYAK",1+SUMPRODUCT(($AE$6:$AE$19="LAYAK")*($AD$6:$AD$19>AD19)),"") | AG19: =IF(AE19="LAYAK",IF(SUMPRODUCT(($AE$6:$AE$19="LAYAK")*($AD$6:$AD$19=AD19))>1,"SERI: jawatankuasa putuskan",""),"")
B20: Bil undian juri | D20: =COUNT(D6:D19) | E20: =COUNT(E6:E19) | F20: =COUNT(F6:F19) | G20: =COUNT(G6:G19) | H20: =COUNT(H6:H19) | I20: =COUNT(I6:I19) | J20: =COUNT(J6:J19) | K20: =COUNT(K6:K19) | ... AB20: =COUNT(AB6:AB19) | AC20: =COUNTIF(D20:AB20,">0")&" daripada 25 juri mengundi"
B21: Jumlah sumbangan juri | D21: =ROUND(SUM(D6:D19)/30*4,2) | E21: =ROUND(SUM(E6:E19)/30*4,2) | F21: =ROUND(SUM(F6:F19)/30*4,2) | G21: =ROUND(SUM(G6:G19)/30*4,2) | H21: =ROUND(SUM(H6:H19)/30*4,2) | I21: =ROUND(SUM(I6:I19)/30*4,2) | J21: =ROUND(SUM(J6:J19)/30*4,2) | K21: =ROUND(SUM(K6:K19)/30*4,2) | ... AB21: =ROUND(SUM(AB6:AB19)/30*4,2)

Sheet PECAH_SERI
A1: PECAH SERI | pengiraan kedudukan hakim
A2: Tab pengiraan, jangan ubah. Kunci akhir = markah akhir x 100. Lajur komponen = jumlah tiga hakim ikut susunan pecah seri.
A5: Negeri | B5: Layak (1/0) | C5: Kunci akhir | D5: K1 Kreativiti | E5: K2 Kandungan | F5: K3 Canva | G5: K4 AI | H5: K5 CapCut | I5: K6 Audio | J5: K7 Persembahan | K5: K8 Etika | L5: K9 AURORA | M5: KEDUDUKAN | N5: Catatan
A6: =KEPUTUSAN!B6 | B6: =IF(AND(KEPUTUSAN!D6="Aktif",KEPUTUSAN!H6=3),1,0) | C6: =IF(B6=1,ROUND(KEPUTUSAN!I6*100,0),0) | D6: =IF($B6=1,HAKIM_H1!B6+HAKIM_H2!B6+HAKIM_H3!B6,0) | E6: =IF($B6=1,HAKIM_H1!C6+HAKIM_H2!C6+HAKIM_H3!C6,0) | F6: =IF($B6=1,HAKIM_H1!D6+HAKIM_H2!D6+HAKIM_H3!D6,0) | G6: =IF($B6=1,HAKIM_H1!E6+HAKIM_H2!E6+HAKIM_H3!E6,0) | H6: =IF($B6=1,HAKIM_H1!F6+HAKIM_H2!F6+HAKIM_H3!F6,0) | I6: =IF($B6=1,HAKIM_H1!G6+HAKIM_H2!G6+HAKIM_H3!G6,0) | J6: =IF($B6=1,HAKIM_H1!I6+HAKIM_H2!I6+HAKIM_H3!I6,0) | K6: =IF($B6=1,HAKIM_H1!H6+HAKIM_H2!H6+HAKIM_H3!H6,0) | L6: =IF($B6=1,HAKIM_H1!J6+HAKIM_H2!J6+HAKIM_H3!J6,0) | M6: =IF(B6=1,1+SUMPRODUCT($B$6:$B$19*(($C$6:$C$19>C6)+($C$6:$C$19=C6)*(($D$6:$D$19>D6)+($D$6:$D$19=D6)*(($E$6:$E$19>E6)+($E$6:$E$19=E6)*(($F$6:$F$19>F6)+($F$6:$F$19=F6)*(($G$6:$G$19>G6)+($G$6:$G$19=G6)*(($H$6:$H$19>H6)+($H$6:$H$19=H6)*(($I$6:$I$19>I6)+($I$6:$I$19=I6)*(($J$6:$J$19>J6)+($J$6:$J$19=J6)*(($K$6:$K$19>K6)+($K$6:$K$19=K6)*($L$6:$L$19>L6))))))))))),"") | N6: =IF(B6=1,IF(SUMPRODUCT($B$6:$B$19*($C$6:$C$19=C6)*($D$6:$D$19=D6)*($E$6:$E$19=E6)*($F$6:$F$19=F6)*($G$6:$G$19=G6)*($H$6:$H$19=H6)*($I$6:$I$19=I6)*($J$6:$J$19=J6)*($K$6:$K$19=K6)*($L$6:$L$19=L6))>1,"SERI PENUH: panel berbincang dan rekod keputusan",""),"")
A7: =KEPUTUSAN!B7 | B7: =IF(AND(KEPUTUSAN!D7="Aktif",KEPUTUSAN!H7=3),1,0) | C7: =IF(B7=1,ROUND(KEPUTUSAN!I7*100,0),0) | D7: =IF($B7=1,HAKIM_H1!B7+HAKIM_H2!B7+HAKIM_H3!B7,0) | E7: =IF($B7=1,HAKIM_H1!C7+HAKIM_H2!C7+HAKIM_H3!C7,0) | F7: =IF($B7=1,HAKIM_H1!D7+HAKIM_H2!D7+HAKIM_H3!D7,0) | G7: =IF($B7=1,HAKIM_H1!E7+HAKIM_H2!E7+HAKIM_H3!E7,0) | H7: =IF($B7=1,HAKIM_H1!F7+HAKIM_H2!F7+HAKIM_H3!F7,0) | I7: =IF($B7=1,HAKIM_H1!G7+HAKIM_H2!G7+HAKIM_H3!G7,0) | J7: =IF($B7=1,HAKIM_H1!I7+HAKIM_H2!I7+HAKIM_H3!I7,0) | K7: =IF($B7=1,HAKIM_H1!H7+HAKIM_H2!H7+HAKIM_H3!H7,0) | L7: =IF($B7=1,HAKIM_H1!J7+HAKIM_H2!J7+HAKIM_H3!J7,0) | M7: =IF(B7=1,1+SUMPRODUCT($B$6:$B$19*(($C$6:$C$19>C7)+($C$6:$C$19=C7)*(($D$6:$D$19>D7)+($D$6:$D$19=D7)*(($E$6:$E$19>E7)+($E$6:$E$19=E7)*(($F$6:$F$19>F7)+($F$6:$F$19=F7)*(($G$6:$G$19>G7)+($G$6:$G$19=G7)*(($H$6:$H$19>H7)+($H$6:$H$19=H7)*(($I$6:$I$19>I7)+($I$6:$I$19=I7)*(($J$6:$J$19>J7)+($J$6:$J$19=J7)*(($K$6:$K$19>K7)+($K$6:$K$19=K7)*($L$6:$L$19>L7))))))))))),"") | N7: =IF(B7=1,IF(SUMPRODUCT($B$6:$B$19*($C$6:$C$19=C7)*($D$6:$D$19=D7)*($E$6:$E$19=E7)*($F$6:$F$19=F7)*($G$6:$G$19=G7)*($H$6:$H$19=H7)*($I$6:$I$19=I7)*($J$6:$J$19=J7)*($K$6:$K$19=K7)*($L$6:$L$19=L7))>1,"SERI PENUH: panel berbincang dan rekod keputusan",""),"")
A8: =KEPUTUSAN!B8 | B8: =IF(AND(KEPUTUSAN!D8="Aktif",KEPUTUSAN!H8=3),1,0) | C8: =IF(B8=1,ROUND(KEPUTUSAN!I8*100,0),0) | D8: =IF($B8=1,HAKIM_H1!B8+HAKIM_H2!B8+HAKIM_H3!B8,0) | E8: =IF($B8=1,HAKIM_H1!C8+HAKIM_H2!C8+HAKIM_H3!C8,0) | F8: =IF($B8=1,HAKIM_H1!D8+HAKIM_H2!D8+HAKIM_H3!D8,0) | G8: =IF($B8=1,HAKIM_H1!E8+HAKIM_H2!E8+HAKIM_H3!E8,0) | H8: =IF($B8=1,HAKIM_H1!F8+HAKIM_H2!F8+HAKIM_H3!F8,0) | I8: =IF($B8=1,HAKIM_H1!G8+HAKIM_H2!G8+HAKIM_H3!G8,0) | J8: =IF($B8=1,HAKIM_H1!I8+HAKIM_H2!I8+HAKIM_H3!I8,0) | K8: =IF($B8=1,HAKIM_H1!H8+HAKIM_H2!H8+HAKIM_H3!H8,0) | L8: =IF($B8=1,HAKIM_H1!J8+HAKIM_H2!J8+HAKIM_H3!J8,0) | M8: =IF(B8=1,1+SUMPRODUCT($B$6:$B$19*(($C$6:$C$19>C8)+($C$6:$C$19=C8)*(($D$6:$D$19>D8)+($D$6:$D$19=D8)*(($E$6:$E$19>E8)+($E$6:$E$19=E8)*(($F$6:$F$19>F8)+($F$6:$F$19=F8)*(($G$6:$G$19>G8)+($G$6:$G$19=G8)*(($H$6:$H$19>H8)+($H$6:$H$19=H8)*(($I$6:$I$19>I8)+($I$6:$I$19=I8)*(($J$6:$J$19>J8)+($J$6:$J$19=J8)*(($K$6:$K$19>K8)+($K$6:$K$19=K8)*($L$6:$L$19>L8))))))))))),"") | N8: =IF(B8=1,IF(SUMPRODUCT($B$6:$B$19*($C$6:$C$19=C8)*($D$6:$D$19=D8)*($E$6:$E$19=E8)*($F$6:$F$19=F8)*($G$6:$G$19=G8)*($H$6:$H$19=H8)*($I$6:$I$19=I8)*($J$6:$J$19=J8)*($K$6:$K$19=K8)*($L$6:$L$19=L8))>1,"SERI PENUH: panel berbincang dan rekod keputusan",""),"")
A9: =KEPUTUSAN!B9 | B9: =IF(AND(KEPUTUSAN!D9="Aktif",KEPUTUSAN!H9=3),1,0) | C9: =IF(B9=1,ROUND(KEPUTUSAN!I9*100,0),0) | D9: =IF($B9=1,HAKIM_H1!B9+HAKIM_H2!B9+HAKIM_H3!B9,0) | E9: =IF($B9=1,HAKIM_H1!C9+HAKIM_H2!C9+HAKIM_H3!C9,0) | F9: =IF($B9=1,HAKIM_H1!D9+HAKIM_H2!D9+HAKIM_H3!D9,0) | G9: =IF($B9=1,HAKIM_H1!E9+HAKIM_H2!E9+HAKIM_H3!E9,0) | H9: =IF($B9=1,HAKIM_H1!F9+HAKIM_H2!F9+HAKIM_H3!F9,0) | I9: =IF($B9=1,HAKIM_H1!G9+HAKIM_H2!G9+HAKIM_H3!G9,0) | J9: =IF($B9=1,HAKIM_H1!I9+HAKIM_H2!I9+HAKIM_H3!I9,0) | K9: =IF($B9=1,HAKIM_H1!H9+HAKIM_H2!H9+HAKIM_H3!H9,0) | L9: =IF($B9=1,HAKIM_H1!J9+HAKIM_H2!J9+HAKIM_H3!J9,0) | M9: =IF(B9=1,1+SUMPRODUCT($B$6:$B$19*(($C$6:$C$19>C9)+($C$6:$C$19=C9)*(($D$6:$D$19>D9)+($D$6:$D$19=D9)*(($E$6:$E$19>E9)+($E$6:$E$19=E9)*(($F$6:$F$19>F9)+($F$6:$F$19=F9)*(($G$6:$G$19>G9)+($G$6:$G$19=G9)*(($H$6:$H$19>H9)+($H$6:$H$19=H9)*(($I$6:$I$19>I9)+($I$6:$I$19=I9)*(($J$6:$J$19>J9)+($J$6:$J$19=J9)*(($K$6:$K$19>K9)+($K$6:$K$19=K9)*($L$6:$L$19>L9))))))))))),"") | N9: =IF(B9=1,IF(SUMPRODUCT($B$6:$B$19*($C$6:$C$19=C9)*($D$6:$D$19=D9)*($E$6:$E$19=E9)*($F$6:$F$19=F9)*($G$6:$G$19=G9)*($H$6:$H$19=H9)*($I$6:$I$19=I9)*($J$6:$J$19=J9)*($K$6:$K$19=K9)*($L$6:$L$19=L9))>1,"SERI PENUH: panel berbincang dan rekod keputusan",""),"")
A10: =KEPUTUSAN!B10 | B10: =IF(AND(KEPUTUSAN!D10="Aktif",KEPUTUSAN!H10=3),1,0) | C10: =IF(B10=1,ROUND(KEPUTUSAN!I10*100,0),0) | D10: =IF($B10=1,HAKIM_H1!B10+HAKIM_H2!B10+HAKIM_H3!B10,0) | E10: =IF($B10=1,HAKIM_H1!C10+HAKIM_H2!C10+HAKIM_H3!C10,0) | F10: =IF($B10=1,HAKIM_H1!D10+HAKIM_H2!D10+HAKIM_H3!D10,0) | G10: =IF($B10=1,HAKIM_H1!E10+HAKIM_H2!E10+HAKIM_H3!E10,0) | H10: =IF($B10=1,HAKIM_H1!F10+HAKIM_H2!F10+HAKIM_H3!F10,0) | I10: =IF($B10=1,HAKIM_H1!G10+HAKIM_H2!G10+HAKIM_H3!G10,0) | J10: =IF($B10=1,HAKIM_H1!I10+HAKIM_H2!I10+HAKIM_H3!I10,0) | K10: =IF($B10=1,HAKIM_H1!H10+HAKIM_H2!H10+HAKIM_H3!H10,0) | L10: =IF($B10=1,HAKIM_H1!J10+HAKIM_H2!J10+HAKIM_H3!J10,0) | M10: =IF(B10=1,1+SUMPRODUCT($B$6:$B$19*(($C$6:$C$19>C10)+($C$6:$C$19=C10)*(($D$6:$D$19>D10)+($D$6:$D$19=D10)*(($E$6:$E$19>E10)+($E$6:$E$19=E10)*(($F$6:$F$19>F10)+($F$6:$F$19=F10)*(($G$6:$G$19>G10)+($G$6:$G$19=G10)*(($H$6:$H$19>H10)+($H$6:$H$19=H10)*(($I$6:$I$19>I10)+($I$6:$I$19=I10)*(($J$6:$J$19>J10)+($J$6:$J$19=J10)*(($K$6:$K$19>K10)+($K$6:$K$19=K10)*($L$6:$L$19>L10))))))))))),"") | N10: =IF(B10=1,IF(SUMPRODUCT($B$6:$B$19*($C$6:$C$19=C10)*($D$6:$D$19=D10)*($E$6:$E$19=E10)*($F$6:$F$19=F10)*($G$6:$G$19=G10)*($H$6:$H$19=H10)*($I$6:$I$19=I10)*($J$6:$J$19=J10)*($K$6:$K$19=K10)*($L$6:$L$19=L10))>1,"SERI PENUH: panel berbincang dan rekod keputusan",""),"")
